Workbook

Sheet 目次
A5: お直し限界値早見表 | B5: お直し限界値早見表 | D5: ビジカジ総裏判定 | E5: ビジカジ総裏 生地替え再製作可否シート
B7: お直し対応シート1
A8: 新宿 | B8: お直し対応シート2 | E8: OPEX原因分類定義一覧
E9: ポロシャツサイズわかるくん
A10: 吉祥寺 | B10: お直し対応シート | D10: その他 | E10: CS受付可能範囲
A12: MODI | B12: お直し対応シート
B14: お直し対応シート1 | D14: 関西用 | E14: こちらのシート
A15: 日本橋 | B15: お直し対応シート2
B17: お直し対応シート1
A18: 有楽町 | B18: お直し対応シート2
B20: お直し対応シート1
A21: 横浜 | B21: お直し対応シート2
A23: ウィメンズ | B23: お直し対応シート
A26: 表参道 | B26: お直し対応シート1
E32: 新お直し入庫処理伝票
E33: 再製作品送付伝票
D34: 配送伝票 | E34: 縫製汚れ伝票
E37: お直し預かり票印刷用 - スーツ
D38: 印刷物 | E38: お直し品預かり票印刷用 - シャツ

Sheet 新アイテム別限界値判別早見表
A1: =IFERROR(__xludf.DUMMYFUNCTION("IMPORTRANGE(""1rvkHoPE2oZB-0k4vlmjA8cgHMdBuXe9EcqpHysy6UW8"", ""'新アイテム別限界値判別早見表（作業中）'!A:BE"") "),"") | C1: =IFERROR(__xludf.DUMMYFUNCTION("""COMPUTED_VALUE"""),45991.0) -> 45991
B2: =IFERROR(__xludf.DUMMYFUNCTION("""COMPUTED_VALUE"""),"再製作") -> 再製作 | C2: =IFERROR(__xludf.DUMMYFUNCTION("""COMPUTED_VALUE"""),"基本WEB表示納期 ダブルセッティング生地は、業務チーム確認") -> 基本WEB表示納期 ダブルセッティング生地は、業務チーム確認
B3: =IFERROR(__xludf.DUMMYFUNCTION("""COMPUTED_VALUE"""),"1箇所納期") -> 1箇所納期 | C3: =IFERROR(__xludf.DUMMYFUNCTION("""COMPUTED_VALUE"""),"各項目ごとに設定された納期を参照") -> 各項目ごとに設定された納期を参照
B4: =IFERROR(__xludf.DUMMYFUNCTION("""COMPUTED_VALUE"""),"上物納期：（2箇所以内）") -> 上物納期：（2箇所以内） | C4: =IFERROR(__xludf.DUMMYFUNCTION("""COMPUTED_VALUE"""),46003.0) -> 46003 | E4: =IFERROR(__xludf.DUMMYFUNCTION("""COMPUTED_VALUE"""),"上物納期：（3箇所以上）") -> 上物納期：（3箇所以上） | H4: =IFERROR(__xludf.DUMMYFUNCTION("""COMPUTED_VALUE"""),46008.0) -> 46008
B5: =IFERROR(__xludf.DUMMYFUNCTION("""COMPUTED_VALUE"""),"下物納期：（2箇所以内）") -> 下物納期：（2箇所以内） | C5: =IFERROR(__xludf.DUMMYFUNCTION("""COMPUTED_VALUE"""),46002.0) -> 46002 | E5: =IFERROR(__xludf.DUMMYFUNCTION("""COMPUTED_VALUE"""),"下物納期：（3箇所以上）") -> 下物納期：（3箇所以上） | H5: =IFERROR(__xludf.DUMMYFUNCTION("""COMPUTED_VALUE"""),46007.0) -> 46007
B7: =IFERROR(__xludf.DUMMYFUNCTION("""COMPUTED_VALUE"""),"袖丈・裄丈・股下は左右であっても1箇所換算でOK") -> 袖丈・裄丈・股下は左右であっても1箇所換算でOK
B8: =IFERROR(__xludf.DUMMYFUNCTION("""COMPUTED_VALUE"""),"スーツ上下、3Pでお直しが発生した場合、納期は長い方（上物）に合わせてください。") -> スーツ上下、3Pでお直しが発生した場合、納期は長い方（上物）に合わせてください。
B11: =IFERROR(__xludf.DUMMYFUNCTION("""COMPUTED_VALUE"""),"上物納期") -> 上物納期 | AD11: =IFERROR(__xludf.DUMMYFUNCTION("""COMPUTED_VALUE"""),"下物納期") -> 下物納期 | BB11: =IFERROR(__xludf.DUMMYFUNCTION("""COMPUTED_VALUE"""),"特殊生地一覧") -> 特殊生地一覧
B12: =IFERROR(__xludf.DUMMYFUNCTION("""COMPUTED_VALUE"""),"アイテム") -> アイテム | C12: =IFERROR(__xludf.DUMMYFUNCTION("""COMPUTED_VALUE"""),"ジャンル") -> ジャンル | D12: =IFERROR(__xludf.DUMMYFUNCTION("""COMPUTED_VALUE"""),"部位") -> 部位 | E12: =IFERROR(__xludf.DUMMYFUNCTION("""COMPUTED_VALUE"""),"カスタマイズや条件") -> カスタマイズや条件 | F12: =IFERROR(__xludf.DUMMYFUNCTION("""COMPUTED_VALUE"""),"←詰め") -> ←詰め | Q12: =IFERROR(__xludf.DUMMYFUNCTION("""COMPUTED_VALUE"""),"出し→") -> 出し→ | V12: =IFERROR(__xludf.DUMMYFUNCTION("""COMPUTED_VALUE"""),"営業日") -> 営業日 | W12: =IFERROR(__xludf.DUMMYFUNCTION("""COMPUTED_VALUE"""),"1箇所納期") -> 1箇所納期 | X12: =IFERROR(__xludf.DUMMYFUNCTION("""COMPUTED_VALUE"""),"2箇所納期") -> 2箇所納期 | Y12: =IFERROR(__xludf.DUMMYFUNCTION("""COMPUTED_VALUE"""),"3箇所以上") -> 3箇所以上 | Z12: =IFERROR(__xludf.DUMMYFUNCTION("""COMPUTED_VALUE"""),"サポ外料金 （原価）") -> サポ外料金 （原価） | AA12: =IFERROR(__xludf.DUMMYFUNCTION("""COMPUTED_VALUE"""),"サポ外料金 現状（請求）") -> サポ外料金 現状（請求） | AB12: =IFERROR(__xludf.DUMMYFUNCTION("""COMPUTED_VALUE"""),"サポ外料金 新（請求）") -> サポ外料金 新（請求） | AD12: =IFERROR(__xludf.DUMMYFUNCTION("""COMPUTED_VALUE"""),"アイテム") -> アイテム | AE12: =IFERROR(__xludf.DUMMYFUNCTION("""COMPUTED_VALUE"""),"ジャンル") -> ジャンル | AF12: =IFERROR(__xludf.DUMMYFUNCTION("""COMPUTED_VALUE"""),"部位") -> 部位 | AG12: =IFERROR(__xludf.DUMMYFUNCTION("""COMPUTED_VALUE"""),"カスタマイズや条件") -> カスタマイズや条件 | AH12: =IFERROR(__xludf.DUMMYFUNCTION("""COMPUTED_VALUE"""),"←詰め") -> ←詰め | AO12: =IFERROR(__xludf.DUMMYFUNCTION("""COMPUTED_VALUE"""),"出し→") -> 出し→ | AT12: =IFERROR(__xludf.DUMMYFUNCTION("""COMPUTED_VALUE"""),"営業日") -> 営業日 | AU12: =IFERROR(__xludf.DUMMYFUNCTION("""COMPUTED_VALUE"""),"1箇所納期") -> 1箇所納期 | AV12: =IFERROR(__xludf.DUMMYFUNCTION("""COMPUTED_VALUE"""),"2箇所納期") -> 2箇所納期 | AW12: =IFERROR(__xludf.DUMMYFUNCTION("""COMPUTED_VALUE"""),"3箇所以上") -> 3箇所以上 | AX12: =IFERROR(__xludf.DUMMYFUNCTION("""COMPUTED_VALUE"""),"サポ外料金 （原価）") -> サポ外料金 （原価） | AY12: =IFERROR(__xludf.DUMMYFUNCTION("""COMPUTED_VALUE"""),"サポ外料金 現状（請求）") -> サポ外料金 現状（請求） | AZ12: =IFERROR(__xludf.DUMMYFUNCTION("""COMPUTED_VALUE"""),"サポ外料金 新（請求）") -> サポ外料金 新（請求） | BB12: =IFERROR(__xludf.DUMMYFUNCTION("""COMPUTED_VALUE"""),"商品名") -> 商品名 | BC12: =IFERROR(__xludf.DUMMYFUNCTION("""COMPUTED_VALUE"""),"生地コード") -> 生地コード | BD12: =IFERROR(__xludf.DUMMYFUNCTION("""COMPUTED_VALUE"""),"特殊対応内容") -> 特殊対応内容
B13: =IFERROR(__xludf.DUMMYFUNCTION("""COMPUTED_VALUE""")," ジャケット カジュアルジャケット ジャコット") -> ジャケット カジュアルジャケット ジャコット | C13: =IFERROR(__xludf.DUMMYFUNCTION("""COMPUTED_VALUE"""),"サイズ") -> サイズ | D13: =IFERROR(__xludf.DUMMYFUNCTION("""COMPUTED_VALUE"""),"肩巾") -> 肩巾 | F13: =IFERROR(__xludf.DUMMYFUNCTION("""COMPUTED_VALUE"""),-10.0) -> -10 | G13: =IFERROR(__xludf.DUMMYFUNCTION("""COMPUTED_VALUE"""),-9.0) -> -9 | H13: =IFERROR(__xludf.DUMMYFUNCTION("""COMPUTED_VALUE"""),-8.0) -> -8 | I13: =IFERROR(__xludf.DUMMYFUNCTION("""COMPUTED_VALUE"""),-7.0) -> -7 | J13: =IFERROR(__xludf.DUMMYFUNCTION("""COMPUTED_VALUE"""),-6.0) -> -6 | K13: =IFERROR(__xludf.DUMMYFUNCTION("""COMPUTED_VALUE"""),-5.0) -> -5 | L13: =IFERROR(__xludf.DUMMYFUNCTION("""COMPUTED_VALUE"""),-4.0) -> -4 | M13: =IFERROR(__xludf.DUMMYFUNCTION("""COMPUTED_VALUE"""),-3.0) -> -3 | N13: =IFERROR(__xludf.DUMMYFUNCTION("""COMPUTED_VALUE"""),-2.0) -> -2 | O13: =IFERROR(__xludf.DUMMYFUNCTION("""COMPUTED_VALUE"""),-1.0) -> -1 | P13: =IFERROR(__xludf.DUMMYFUNCTION("""COMPUTED_VALUE"""),0.0) -> 0 | Q13: =IFERROR(__xludf.DUMMYFUNCTION("""COMPUTED_VALUE"""),0.5) -> 0.5 | R13: =IFERROR(__xludf.DUMMYFUNCTION("""COMPUTED_VALUE"""),1.0) -> 1 | S13: =IFERROR(__xludf.DUMMYFUNCTION("""COMPUTED_VALUE"""),2.0) -> 2 | T13: =IFERROR(__xludf.DUMMYFUNCTION("""COMPUTED_VALUE"""),3.0) -> 3 | U13: =IFERROR(__xludf.DUMMYFUNCTION("""COMPUTED_VALUE"""),4.0) -> 4 | V13: =IFERROR(__xludf.DUMMYFUNCTION("""COMPUTED_VALUE"""),7.0) -> 7 | W13: =IFERROR(__xludf.DUMMYFUNCTION("""COMPUTED_VALUE"""),46000.0) -> 46000 | X13: =IFERROR(__xludf.DUMMYFUNCTION("""COMPUTED_VALUE"""),46003.0) -> 46003 | Y13: =IFERROR(__xludf.DUMMYFUNCTION("""COMPUTED_VALUE"""),46008.0) -> 46008 | Z13: =IFERROR(__xludf.DUMMYFUNCTION("""COMPUTED_VALUE"""),3500.0) -> 3500 | AD13: =IFERROR(__xludf.DUMMYFUNCTION("""COMPUTED_VALUE"""),"スラックス カジュアルパンツ") -> スラックス カジュアルパンツ | AE13: =IFERROR(__xludf.DUMMYFUNCTION("""COMPUTED_VALUE"""),"サイズ") -> サイズ | AF13: =IFERROR(__xludf.DUMMYFUNCTION("""COMPUTED_VALUE"""),"ウエスト") -> ウエスト | AH13: =IFERROR(__xludf.DUMMYFUNCTION("""COMPUTED_VALUE"""),-6.0) -> -6 | AI13: =IFERROR(__xludf.DUMMYFUNCTION("""COMPUTED_VALUE"""),-5.0) -> -5 | AJ13: =IFERROR(__xludf.DUMMYFUNCTION("""COMPUTED_VALUE"""),-4.0) -> -4 | AK13: =IFERROR(__xludf.DUMMYFUNCTION("""COMPUTED_VALUE"""),-3.0) -> -3 | AL13: =IFERROR(__xludf.DUMMYFUNCTION("""COMPUTED_VALUE"""),-2.0) -> -2 | AM13: =IFERROR(__xludf.DUMMYFUNCTION("""COMPUTED_VALUE"""),-1.0) -> -1 | AN13: =IFERROR(__xludf.DUMMYFUNCTION("""COMPUTED_VALUE"""),0.0) -> 0 | AO13: =IFERROR(__xludf.DUMMYFUNCTION("""COMPUTED_VALUE"""),1.0) -> 1 | AP13: =IFERROR(__xludf.DUMMYFUNCTION("""COMPUTED_VALUE"""),2.0) -> 2 | AQ13: =IFERROR(__xludf.DUMMYFUNCTION("""COMPUTED_VALUE"""),3.0) -> 3 | AR13: =IFERROR(__xludf.DUMMYFUNCTION("""COMPUTED_VALUE"""),4.0) -> 4 | AS13: =IFERROR(__xludf.DUMMYFUNCTION("""COMPUTED_VALUE"""),5.0) -> 5 | AT13: =IFERROR(__xludf.DUMMYFUNCTION("""COMPUTED_VALUE"""),5.0) -> 5 | AU13: =IFERROR(__xludf.DUMMYFUNCTION("""COMPUTED_VALUE"""),45996.0) -> 45996 | AV13: =IFERROR(__xludf.DUMMYFUNCTION("""COMPUTED_VALUE"""),46002.0) -> 46002 | AW13: =IFERROR(__xludf.DUMMYFUNCTION("""COMPUTED_VALUE"""),46007.0) -> 46007 | BB13: =IFERROR(__xludf.DUMMYFUNCTION("""COMPUTED_VALUE"""),"EASY CARE COTTON JAPAN FABRIC from BANSHU") -> EASY CARE COTTON JAPAN FABRIC from BANSHU | BC13: =IFERROR(__xludf.DUMMYFUNCTION("""COMPUTED_VALUE"""),"C220355〜C220359") -> C220355〜C220359 | BD13: =IFERROR(__xludf.DUMMYFUNCTION("""COMPUTED_VALUE"""),"出しNG（再製作）ジャケット・スラックス・") -> 出しNG（再製作）ジャケット・スラックス・
D14: =IFERROR(__xludf.DUMMYFUNCTION("""COMPUTED_VALUE"""),"袖丈") -> 袖丈 | E14: =IFERROR(__xludf.DUMMYFUNCTION("""COMPUTED_VALUE"""),"本切羽有り") -> 本切羽有り | F14: =IFERROR(__xludf.DUMMYFUNCTION("""COMPUTED_VALUE"""),-10.0) -> -10 | G14: =IFERROR(__xludf.DUMMYFUNCTION("""COMPUTED_VALUE"""),-9.0) -> -9 | H14: =IFERROR(__xludf.DUMMYFUNCTION("""COMPUTED_VALUE"""),-8.0) -> -8 | I14: =IFERROR(__xludf.DUMMYFUNCTION("""COMPUTED_VALUE"""),-7.0) -> -7 | J14: =IFERROR(__xludf.DUMMYFUNCTION("""COMPUTED_VALUE"""),-6.0) -> -6 | K14: =IFERROR(__xludf.DUMMYFUNCTION("""COMPUTED_VALUE"""),-5.0) -> -5 | L14: =IFERROR(__xludf.DUMMYFUNCTION("""COMPUTED_VALUE"""),-4.0) -> -4 | M14: =IFERROR(__xludf.DUMMYFUNCTION("""COMPUTED_VALUE"""),-3.0) -> -3 | N14: =IFERROR(__xludf.DUMMYFUNCTION("""COMPUTED_VALUE"""),-2.0) -> -2 | O14: =IFERROR(__xludf.DUMMYFUNCTION("""COMPUTED_VALUE"""),-1.0) -> -1 | P14: =IFERROR(__xludf.DUMMYFUNCTION("""COMPUTED_VALUE"""),0.0) -> 0 | Q14: =IFERROR(__xludf.DUMMYFUNCTION("""COMPUTED_VALUE"""),0.5) -> 0.5 | R14: =IFERROR(__xludf.DUMMYFUNCTION("""COMPUTED_VALUE"""),1.0) -> 1 | S14: =IFERROR(__xludf.DUMMYFUNCTION("""COMPUTED_VALUE"""),2.0) -> 2 | T14: =IFERROR(__xludf.DUMMYFUNCTION("""COMPUTED_VALUE"""),3.0) -> 3 | U14: =IFERROR(__xludf.DUMMYFUNCTION("""COMPUTED_VALUE"""),4.0) -> 4 | V14: =IFERROR(__xludf.DUMMYFUNCTION("""COMPUTED_VALUE"""),8.0) -> 8 | W14: =IFERROR(__xludf.DUMMYFUNCTION("""COMPUTED_VALUE"""),46001.0) -> 46001 | X14: =IFERROR(__xludf.DUMMYFUNCTION("""COMPUTED_VALUE"""),46003.0) -> 46003 | Y14: =IFERROR(__xludf.DUMMYFUNCTION("""COMPUTED_VALUE"""),46008.0) -> 46008 | Z14: =IFERROR(__xludf.DUMMYFUNCTION("""COMPUTED_VALUE"""),6500.0) -> 6500 | AF14: =IFERROR(__xludf.DUMMYFUNCTION("""COMPUTED_VALUE"""),"股上") -> 股上 | AH14: =IFERROR(__xludf.DUMMYFUNCTION("""COMPUTED_VALUE"""),-6.0) -> -6 | AI14: =IFERROR(__xludf.DUMMYFUNCTION("""COMPUTED_VALUE"""),-5.0) -> -5 | AJ14: =IFERROR(__xludf.DUMMYFUNCTION("""COMPUTED_VALUE"""),-3.0) -> -3 | AK14: =IFERROR(__xludf.DUMMYFUNCTION("""COMPUTED_VALUE"""),-2.0) -> -2 | AL14: =IFERROR(__xludf.DUMMYFUNCTION("""COMPUTED_VALUE"""),-1.0) -> -1 | AM14: =IFERROR(__xludf.DUMMYFUNCTION("""COMPUTED_VALUE"""),-0.5) -> -0.5 | AN14: =IFERROR(__xludf.DUMMYFUNCTION("""COMPUTED_VALUE"""),0.0) -> 0 | AO14: =IFERROR(__xludf.DUMMYFUNCTION("""COMPUTED_VALUE"""),0.5) -> 0.5 | AP14: =IFERROR(__xludf.DUMMYFUNCTION("""COMPUTED_VALUE"""),2.0) -> 2 | AQ14: =IFERROR(__xludf.DUMMYFUNCTION("""COMPUTED_VALUE"""),3.0) -> 3 | AR14: =IFERROR(__xludf.DUMMYFUNCTION("""COMPUTED_VALUE"""),4.0) -> 4 | AS14: =IFERROR(__xludf.DUMMYFUNCTION("""COMPUTED_VALUE"""),5.0) -> 5 | AT14: =IFERROR(__xludf.DUMMYFUNCTION("""COMPUTED_VALUE"""),7.0) -> 7 | AU14: =IFERROR(__xludf.DUMMYFUNCTION("""COMPUTED_VALUE"""),46000.0) -> 46000 | AV14: =IFERROR(__xludf.DUMMYFUNCTION("""COMPUTED_VALUE"""),46002.0) -> 46002 | AW14: =IFERROR(__xludf.DUMMYFUNCTION("""COMPUTED_VALUE"""),46007.0) -> 46007 | BB14: =IFERROR(__xludf.DUMMYFUNCTION("""COMPUTED_VALUE"""),"BUCOL FRENCH GABARDINE") -> BUCOL FRENCH GABARDINE | BC14: =IFERROR(__xludf.DUMMYFUNCTION("""COMPUTED_VALUE"""),"A230233〜A230234") -> A230233〜A230234 | BD14: =IFERROR(__xludf.DUMMYFUNCTION("""COMPUTED_VALUE"""),"出しNG（再製作）ジャケット・スラックス") -> 出しNG（再製作）ジャケット・スラックス
E15: =IFERROR(__xludf.DUMMYFUNCTION("""COMPUTED_VALUE"""),"本切羽無し ※±1cmは切羽移動なし") -> 本切羽無し ※±1cmは切羽移動なし | F15: =IFERROR(__xludf.DUMMYFUNCTION("""COMPUTED_VALUE"""),-10.0) -> -10 | G15: =IFERROR(__xludf.DUMMYFUNCTION("""COMPUTED_VALUE"""),-9.0) -> -9 | H15: =IFERROR(__xludf.DUMMYFUNCTION("""COMPUTED_VALUE"""),-8.0) -> -8 | I15: =IFERROR(__xludf.DUMMYFUNCTION("""COMPUTED_VALUE"""),-7.0) -> -7 | J15: =IFERROR(__xludf.DUMMYFUNCTION("""COMPUTED_VALUE"""),-6.0) -> -6 | K15: =IFERROR(__xludf.DUMMYFUNCTION("""COMPUTED_VALUE"""),-5.0) -> -5 | L15: =IFERROR(__xludf.DUMMYFUNCTION("""COMPUTED_VALUE"""),-4.0) -> -4 | M15: =IFERROR(__xludf.DUMMYFUNCTION("""COMPUTED_VALUE"""),-3.0) -> -3 | N15: =IFERROR(__xludf.DUMMYFUNCTION("""COMPUTED_VALUE"""),-2.0) -> -2 | O15: =IFERROR(__xludf.DUMMYFUNCTION("""COMPUTED_VALUE"""),-1.0) -> -1 | P15: =IFERROR(__xludf.DUMMYFUNCTION("""COMPUTED_VALUE"""),0.0) -> 0 | Q15: =IFERROR(__xludf.DUMMYFUNCTION("""COMPUTED_VALUE"""),1.0) -> 1 | R15: =IFERROR(__xludf.DUMMYFUNCTION("""COMPUTED_VALUE"""),2.5) -> 2.5 | S15: =IFERROR(__xludf.DUMMYFUNCTION("""COMPUTED_VALUE"""),3.0) -> 3 | T15: =IFERROR(__xludf.DUMMYFUNCTION("""COMPUTED_VALUE"""),4.0) -> 4 | U15: =IFERROR(__xludf.DUMMYFUNCTION("""COMPUTED_VALUE"""),5.0) -> 5 | V15: =IFERROR(__xludf.DUMMYFUNCTION("""COMPUTED_VALUE"""),7.0) -> 7 | W15: =IFERROR(__xludf.DUMMYFUNCTION("""COMPUTED_VALUE"""),46000.0) -> 46000 | X15: =IFERROR(__xludf.DUMMYFUNCTION("""COMPUTED_VALUE"""),46003.0) -> 46003 | Y15: =IFERROR(__xludf.DUMMYFUNCTION("""COMPUTED_VALUE"""),46008.0) -> 46008 | Z15: =IFERROR(__xludf.DUMMYFUNCTION("""COMPUTED_VALUE"""),1300.0) -> 1300 | AF15: =IFERROR(__xludf.DUMMYFUNCTION("""COMPUTED_VALUE"""),"股下") -> 股下 | AG15: =IFERROR(__xludf.DUMMYFUNCTION("""COMPUTED_VALUE"""),"シングル") -> シングル | AH15: =IFERROR(__xludf.DUMMYFUNCTION("""COMPUTED_VALUE"""),-6.0) -> -6 | AI15: =IFERROR(__xludf.DUMMYFUNCTION("""COMPUTED_VALUE"""),-5.0) -> -5 | AJ15: =IFERROR(__xludf.DUMMYFUNCTION("""COMPUTED_VALUE"""),-4.0) -> -4 | AK15: =IFERROR(__xludf.DUMMYFUNCTION("""COMPUTED_VALUE"""),-3.0) -> -3 | AL15: =IFERROR(__xludf.DUMMYFUNCTION("""COMPUTED_VALUE"""),-2.0) -> -2 | AM15: =IFERROR(__xludf.DUMMYFUNCTION("""COMPUTED_VALUE"""),-1.0) -> -1 | AN15: =IFERROR(__xludf.DUMMYFUNCTION("""COMPUTED_VALUE"""),0.0) -> 0 | AO15: =IFERROR(__xludf.DUMMYFUNCTION("""COMPUTED_VALUE"""),1.0) -> 1 | AP15: =IFERROR(__xludf.DUMMYFUNCTION("""COMPUTED_VALUE"""),2.0) -> 2 | AQ15: =IFERROR(__xludf.DUMMYFUNCTION("""COMPUTED_VALUE"""),3.0) -> 3 | AR15: =IFERROR(__xludf.DUMMYFUNCTION("""COMPUTED_VALUE"""),4.0) -> 4 | AS15: =IFERROR(__xludf.DUMMYFUNCTION("""COMPUTED_VALUE"""),5.0) -> 5 | AT15: =IFERROR(__xludf.DUMMYFUNCTION("""COMPUTED_VALUE"""),5.0) -> 5 | AU15: =IFERROR(__xludf.DUMMYFUNCTION("""COMPUTED_VALUE"""),45996.0) -> 45996 | AV15: =IFERROR(__xludf.DUMMYFUNCTION("""COMPUTED_VALUE"""),46002.0) -> 46002 | AW15: =IFERROR(__xludf.DUMMYFUNCTION("""COMPUTED_VALUE"""),46007.0) -> 46007 | BB15: =IFERROR(__xludf.DUMMYFUNCTION("""COMPUTED_VALUE"""),"SPENCE BRYSON PREMIUM LINEN") -> SPENCE BRYSON PREMIUM LINEN | BC15: =IFERROR(__xludf.DUMMYFUNCTION("""COMPUTED_VALUE"""),"A250036〜A250039") -> A250036〜A250039 | BD15: =IFERROR(__xludf.DUMMYFUNCTION("""COMPUTED_VALUE"""),"出しNG（再製作）ジャケット・スラックス") -> 出しNG（再製作）ジャケット・スラックス
D16: =IFERROR(__xludf.DUMMYFUNCTION("""COMPUTED_VALUE"""),"バスト") -> バスト | F16: =IFERROR(__xludf.DUMMYFUNCTION("""COMPUTED_VALUE"""),-10.0) -> -10 | G16: =IFERROR(__xludf.DUMMYFUNCTION("""COMPUTED_VALUE"""),-9.0) -> -9 | H16: =IFERROR(__xludf.DUMMYFUNCTION("""COMPUTED_VALUE"""),-8.0) -> -8 | I16: =IFERROR(__xludf.DUMMYFUNCTION("""COMPUTED_VALUE"""),-7.0) -> -7 | J16: =IFERROR(__xludf.DUMMYFUNCTION("""COMPUTED_VALUE"""),-6.0) -> -6 | K16: =IFERROR(__xludf.DUMMYFUNCTION("""COMPUTED_VALUE"""),-5.0) -> -5 | L16: =IFERROR(__xludf.DUMMYFUNCTION("""COMPUTED_VALUE"""),-4.0) -> -4 | M16: =IFERROR(__xludf.DUMMYFUNCTION("""COMPUTED_VALUE"""),-3.0) -> -3 | N16: =IFERROR(__xludf.DUMMYFUNCTION("""COMPUTED_VALUE"""),-2.0) -> -2 | O16: =IFERROR(__xludf.DUMMYFUNCTION("""COMPUTED_VALUE"""),-1.0) -> -1 | P16: =IFERROR(__xludf.DUMMYFUNCTION("""COMPUTED_VALUE"""),0.0) -> 0 | Q16: =IFERROR(__xludf.DUMMYFUNCTION("""COMPUTED_VALUE"""),1.0) -> 1 | R16: =IFERROR(__xludf.DUMMYFUNCTION("""COMPUTED_VALUE"""),2.0) -> 2 | S16: =IFERROR(__xludf.DUMMYFUNCTION("""COMPUTED_VALUE"""),3.0) -> 3 | T16: =IFERROR(__xludf.DUMMYFUNCTION("""COMPUTED_VALUE"""),4.0) -> 4 | U16: =IFERROR(__xludf.DUMMYFUNCTION("""COMPUTED_VALUE"""),5.0) -> 5 | V16: =IFERROR(__xludf.DUMMYFUNCTION("""COMPUTED_VALUE"""),7.0) -> 7 | W16: =IFERROR(__xludf.DUMMYFUNCTION("""COMPUTED_VALUE"""),46000.0) -> 46000 | X16: =IFERROR(__xludf.DUMMYFUNCTION("""COMPUTED_VALUE"""),46003.0) -> 46003 | Y16: =IFERROR(__xludf.DUMMYFUNCTION("""COMPUTED_VALUE"""),46008.0) -> 46008 | Z16: =IFERROR(__xludf.DUMMYFUNCTION("""COMPUTED_VALUE"""),3000.0) -> 3000 | AG16: =IFERROR(__xludf.DUMMYFUNCTION("""COMPUTED_VALUE"""),"W幅の3.5cm以下（3cmと3.5cm）のものは、股下1.5cm出しまで") -> W幅の3.5cm以下（3cmと3.5cm）のものは、股下1.5cm出しまで | AH16: =IFERROR(__xludf.DUMMYFUNCTION("""COMPUTED_VALUE"""),-6.0) -> -6 | AI16: =IFERROR(__xludf.DUMMYFUNCTION("""COMPUTED_VALUE"""),-5.0) -> -5 | AJ16: =IFERROR(__xludf.DUMMYFUNCTION("""COMPUTED_VALUE"""),-4.0) -> -4 | AK16: =IFERROR(__xludf.DUMMYFUNCTION("""COMPUTED_VALUE"""),-3.0) -> -3 | AL16: =IFERROR(__xludf.DUMMYFUNCTION("""COMPUTED_VALUE"""),-2.0) -> -2 | AM16: =IFERROR(__xludf.DUMMYFUNCTION("""COMPUTED_VALUE"""),-1.0) -> -1 | AN16: =IFERROR(__xludf.DUMMYFUNCTION("""COMPUTED_VALUE"""),0.0) -> 0 | AO16: =IFERROR(__xludf.DUMMYFUNCTION("""COMPUTED_VALUE"""),1.0) -> 1 | AP16: =IFERROR(__xludf.DUMMYFUNCTION("""COMPUTED_VALUE"""),1.5) -> 1.5 | AQ16: =IFERROR(__xludf.DUMMYFUNCTION("""COMPUTED_VALUE"""),3.0) -> 3 | AR16: =IFERROR(__xludf.DUMMYFUNCTION("""COMPUTED_VALUE"""),4.0) -> 4 | AS16: =IFERROR(__xludf.DUMMYFUNCTION("""COMPUTED_VALUE"""),5.0) -> 5 | AT16: =IFERROR(__xludf.DUMMYFUNCTION("""COMPUTED_VALUE"""),5.0) -> 5 | AU16: =IFERROR(__xludf.DUMMYFUNCTION("""COMPUTED_VALUE"""),45996.0) -> 45996 | AV16: =IFERROR(__xludf.DUMMYFUNCTION("""COMPUTED_VALUE"""),46002.0) -> 46002 | AW16: =IFERROR(__xludf.DUMMYFUNCTION("""COMPUTED_VALUE"""),46007.0) -> 46007 | BB16: =IFERROR(__xludf.DUMMYFUNCTION("""COMPUTED_VALUE"""),"COLOR WOOL") -> COLOR WOOL | BC16: =IFERROR(__xludf.DUMMYFUNCTION("""COMPUTED_VALUE"""),"A210144〜A210153") -> A210144〜A210153 | BD16: =IFERROR(__xludf.DUMMYFUNCTION("""COMPUTED_VALUE"""),"チノパンカテゴリーだが、スラックスと同様出しOK") -> チノパンカテゴリーだが、スラックスと同様出しOK
D17: =IFERROR(__xludf.DUMMYFUNCTION("""COMPUTED_VALUE"""),"着丈") -> 着丈 | F17: =IFERROR(__xludf.DUMMYFUNCTION("""COMPUTED_VALUE"""),-10.0) -> -10 | G17: =IFERROR(__xludf.DUMMYFUNCTION("""COMPUTED_VALUE"""),-9.0) -> -9 | H17: =IFERROR(__xludf.DUMMYFUNCTION("""COMPUTED_VALUE"""),-8.0) -> -8 | I17: =IFERROR(__xludf.DUMMYFUNCTION("""COMPUTED_VALUE"""),-7.0) -> -7 | J17: =IFERROR(__xludf.DUMMYFUNCTION("""COMPUTED_VALUE"""),-6.0) -> -6 | K17: =IFERROR(__xludf.DUMMYFUNCTION("""COMPUTED_VALUE"""),-5.0) -> -5 | L17: =IFERROR(__xludf.DUMMYFUNCTION("""COMPUTED_VALUE"""),-4.0) -> -4 | M17: =IFERROR(__xludf.DUMMYFUNCTION("""COMPUTED_VALUE"""),-3.0) -> -3 | N17: =IFERROR(__xludf.DUMMYFUNCTION("""COMPUTED_VALUE"""),-2.0) -> -2 | O17: =IFERROR(__xludf.DUMMYFUNCTION("""COMPUTED_VALUE"""),-1.0) -> -1 | P17: =IFERROR(__xludf.DUMMYFUNCTION("""COMPUTED_VALUE"""),0.0) -> 0 | Q17: =IFERROR(__xludf.DUMMYFUNCTION("""COMPUTED_VALUE"""),1.0) -> 1 | R17: =IFERROR(__xludf.DUMMYFUNCTION("""COMPUTED_VALUE"""),2.0) -> 2 | S17: =IFERROR(__xludf.DUMMYFUNCTION("""COMPUTED_VALUE"""),3.0) -> 3 | T17: =IFERROR(__xludf.DUMMYFUNCTION("""COMPUTED_VALUE"""),4.0) -> 4 | U17: =IFERROR(__xludf.DUMMYFUNCTION("""COMPUTED_VALUE"""),5.0) -> 5 | V17: =IFERROR(__xludf.DUMMYFUNCTION("""COMPUTED_VALUE"""),7.0) -> 7 | W17: =IFERROR(__xludf.DUMMYFUNCTION("""COMPUTED_VALUE"""),46000.0) -> 46000 | X17: =IFERROR(__xludf.DUMMYFUNCTION("""COMPUTED_VALUE"""),46003.0) -> 46003 | Y17: =IFERROR(__xludf.DUMMYFUNCTION("""COMPUTED_VALUE"""),46008.0) -> 46008 | Z17: =IFERROR(__xludf.DUMMYFUNCTION("""COMPUTED_VALUE"""),3000.0) -> 3000 | AG17: =IFERROR(__xludf.DUMMYFUNCTION("""COMPUTED_VALUE"""),"W幅の4cm以上（4cmと4.5cm）のものは、股下2cm出しまで") -> W幅の4cm以上（4cmと4.5cm）のものは、股下2cm出しまで | AH17: =IFERROR(__xludf.DUMMYFUNCTION("""COMPUTED_VALUE"""),-6.0) -> -6 | AI17: =IFERROR(__xludf.DUMMYFUNCTION("""COMPUTED_VALUE"""),-5.0) -> -5 | AJ17: =IFERROR(__xludf.DUMMYFUNCTION("""COMPUTED_VALUE"""),-4.0) -> -4 | AK17: =IFERROR(__xludf.DUMMYFUNCTION("""COMPUTED_VALUE"""),-3.0) -> -3 | AL17: =IFERROR(__xludf.DUMMYFUNCTION("""COMPUTED_VALUE"""),-2.0) -> -2 | AM17: =IFERROR(__xludf.DUMMYFUNCTION("""COMPUTED_VALUE"""),-1.0) -> -1 | AN17: =IFERROR(__xludf.DUMMYFUNCTION("""COMPUTED_VALUE"""),0.0) -> 0 | AO17: =IFERROR(__xludf.DUMMYFUNCTION("""COMPUTED_VALUE"""),0.5) -> 0.5 | AP17: =IFERROR(__xludf.DUMMYFUNCTION("""COMPUTED_VALUE"""),2.0) -> 2 | AQ17: =IFERROR(__xludf.DUMMYFUNCTION("""COMPUTED_VALUE"""),3.0) -> 3 | AR17: =IFERROR(__xludf.DUMMYFUNCTION("""COMPUTED_VALUE"""),4.0) -> 4 | AS17: =IFERROR(__xludf.DUMMYFUNCTION("""COMPUTED_VALUE"""),5.0) -> 5 | AT17: =IFERROR(__xludf.DUMMYFUNCTION("""COMPUTED_VALUE"""),5.0) -> 5 | AU17: =IFERROR(__xludf.DUMMYFUNCTION("""COMPUTED_VALUE"""),45996.0) -> 45996 | AV17: =IFERROR(__xludf.DUMMYFUNCTION("""COMPUTED_VALUE"""),46002.0) -> 46002 | AW17: =IFERROR(__xludf.DUMMYFUNCTION("""COMPUTED_VALUE"""),46007.0) -> 46007 | BB17: =IFERROR(__xludf.DUMMYFUNCTION("""COMPUTED_VALUE"""),"THE TECH WORK OUT") -> THE TECH WORK OUT | BC17: =IFERROR(__xludf.DUMMYFUNCTION("""COMPUTED_VALUE"""),"C170278〜C170279") -> C170278〜C170279 | BD17: =IFERROR(__xludf.DUMMYFUNCTION("""COMPUTED_VALUE"""),"出しNG（再製作）ジャケット・スラックス") -> 出しNG（再製作）ジャケット・スラックス
D18: =IFERROR(__xludf.DUMMYFUNCTION("""COMPUTED_VALUE"""),"ウエスト") -> ウエスト | E18: =IFERROR(__xludf.DUMMYFUNCTION("""COMPUTED_VALUE"""),"センターベント") -> センターベント | F18: =IFERROR(__xludf.DUMMYFUNCTION("""COMPUTED_VALUE"""),-10.0) -> -10 | G18: =IFERROR(__xludf.DUMMYFUNCTION("""COMPUTED_VALUE"""),-9.0) -> -9 | H18: =IFERROR(__xludf.DUMMYFUNCTION("""COMPUTED_VALUE"""),-8.0) -> -8 | I18: =IFERROR(__xludf.DUMMYFUNCTION("""COMPUTED_VALUE"""),-7.0) -> -7 | J18: =IFERROR(__xludf.DUMMYFUNCTION("""COMPUTED_VALUE"""),-6.0) -> -6 | K18: =IFERROR(__xludf.DUMMYFUNCTION("""COMPUTED_VALUE"""),-5.0) -> -5 | L18: =IFERROR(__xludf.DUMMYFUNCTION("""COMPUTED_VALUE"""),-4.0) -> -4 | M18: =IFERROR(__xludf.DUMMYFUNCTION("""COMPUTED_VALUE"""),-3.0) -> -3 | N18: =IFERROR(__xludf.DUMMYFUNCTION("""COMPUTED_VALUE"""),-2.0) -> -2 | O18: =IFERROR(__xludf.DUMMYFUNCTION("""COMPUTED_VALUE"""),-1.0) -> -1 | P18: =IFERROR(__xludf.DUMMYFUNCTION("""COMPUTED_VALUE"""),0.0) -> 0 | Q18: =IFERROR(__xludf.DUMMYFUNCTION("""COMPUTED_VALUE"""),1.0) -> 1 | R18: =IFERROR(__xludf.DUMMYFUNCTION("""COMPUTED_VALUE"""),2.0) -> 2 | S18: =IFERROR(__xludf.DUMMYFUNCTION("""COMPUTED_VALUE"""),3.0) -> 3 | T18: =IFERROR(__xludf.DUMMYFUNCTION("""COMPUTED_VALUE"""),4.0) -> 4 | U18: =IFERROR(__xludf.DUMMYFUNCTION("""COMPUTED_VALUE"""),5.0) -> 5 | V18: =IFERROR(__xludf.DUMMYFUNCTION("""COMPUTED_VALUE"""),7.0) -> 7 | W18: =IFERROR(__xludf.DUMMYFUNCTION("""COMPUTED_VALUE"""),46000.0) -> 46000 | X18: =IFERROR(__xludf.DUMMYFUNCTION("""COMPUTED_VALUE"""),46003.0) -> 46003 | Y18: =IFERROR(__xludf.DUMMYFUNCTION("""COMPUTED_VALUE"""),46008.0) -> 46008 | Z18: =IFERROR(__xludf.DUMMYFUNCTION("""COMPUTED_VALUE"""),6000.0) -> 6000 | AF18: =IFERROR(__xludf.DUMMYFUNCTION("""COMPUTED_VALUE"""),"ワタリ巾（半寸）") -> ワタリ巾（半寸） | AH18: =IFERROR(__xludf.DUMMYFUNCTION("""COMPUTED_VALUE"""),-6.0) -> -6 | AI18: =IFERROR(__xludf.DUMMYFUNCTION("""COMPUTED_VALUE"""),-5.0) -> -5 | AJ18: =IFERROR(__xludf.DUMMYFUNCTION("""COMPUTED_VALUE"""),-4.0) -> -4 | AK18: =IFERROR(__xludf.DUMMYFUNCTION("""COMPUTED_VALUE"""),-3.0) -> -3 | AL18: =IFERROR(__xludf.DUMMYFUNCTION("""COMPUTED_VALUE"""),-2.0) -> -2 | AM18: =IFERROR(__xludf.DUMMYFUNCTION("""COMPUTED_VALUE"""),-1.0) -> -1 | AN18: =IFERROR(__xludf.DUMMYFUNCTION("""COMPUTED_VALUE"""),0.0) -> 0 | AO18: =IFERROR(__xludf.DUMMYFUNCTION("""COMPUTED_VALUE"""),0.5) -> 0.5 | AP18: =IFERROR(__xludf.DUMMYFUNCTION("""COMPUTED_VALUE"""),2.0) -> 2 | AQ18: =IFERROR(__xludf.DUMMYFUNCTION("""COMPUTED_VALUE"""),3.0) -> 3 | AR18: =IFERROR(__xludf.DUMMYFUNCTION("""COMPUTED_VALUE"""),4.0) -> 4 | AS18: =IFERROR(__xludf.DUMMYFUNCTION("""COMPUTED_VALUE"""),5.0) -> 5 | AT18: =IFERROR(__xludf.DUMMYFUNCTION("""COMPUTED_VALUE"""),5.0) -> 5 | AU18: =IFERROR(__xludf.DUMMYFUNCTION("""COMPUTED_VALUE"""),45996.0) -> 45996 | AV18: =IFERROR(__xludf.DUMMYFUNCTION("""COMPUTED_VALUE"""),46002.0) -> 46002 | AW18: =IFERROR(__xludf.DUMMYFUNCTION("""COMPUTED_VALUE"""),46007.0) -> 46007 | BB18: =IFERROR(__xludf.DUMMYFUNCTION("""COMPUTED_VALUE"""),"KUMOI BEAUTY ORGANIC COTTON CORDUROY") -> KUMOI BEAUTY ORGANIC COTTON CORDUROY | BC18: =IFERROR(__xludf.DUMMYFUNCTION("""COMPUTED_VALUE"""),"C230135〜C230139") -> C230135〜C230139 | BD18: =IFERROR(__xludf.DUMMYFUNCTION("""COMPUTED_VALUE"""),"出しNG（再製作）ジャケット・スラックス") -> 出しNG（再製作）ジャケット・スラックス
E19: =IFERROR(__xludf.DUMMYFUNCTION("""COMPUTED_VALUE"""),"サイドベンツ") -> サイドベンツ | F19: =IFERROR(__xludf.DUMMYFUNCTION("""COMPUTED_VALUE"""),-10.0) -> -10 | G19: =IFERROR(__xludf.DUMMYFUNCTION("""COMPUTED_VALUE"""),-9.0) -> -9 | H19: =IFERROR(__xludf.DUMMYFUNCTION("""COMPUTED_VALUE"""),-8.0) -> -8 | I19: =IFERROR(__xludf.DUMMYFUNCTION("""COMPUTED_VALUE"""),-7.0) -> -7 | J19: =IFERROR(__xludf.DUMMYFUNCTION("""COMPUTED_VALUE"""),-6.0) -> -6 | K19: =IFERROR(__xludf.DUMMYFUNCTION("""COMPUTED_VALUE"""),-5.0) -> -5 | L19: =IFERROR(__xludf.DUMMYFUNCTION("""COMPUTED_VALUE"""),-4.0) -> -4 | M19: =IFERROR(__xludf.DUMMYFUNCTION("""COMPUTED_VALUE"""),-3.0) -> -3 | N19: =IFERROR(__xludf.DUMMYFUNCTION("""COMPUTED_VALUE"""),-2.0) -> -2 | O19: =IFERROR(__xludf.DUMMYFUNCTION("""COMPUTED_VALUE"""),-1.0) -> -1 | P19: =IFERROR(__xludf.DUMMYFUNCTION("""COMPUTED_VALUE"""),0.0) -> 0 | Q19: =IFERROR(__xludf.DUMMYFUNCTION("""COMPUTED_VALUE"""),1.0) -> 1 | R19: =IFERROR(__xludf.DUMMYFUNCTION("""COMPUTED_VALUE"""),2.0) -> 2 | S19: =IFERROR(__xludf.DUMMYFUNCTION("""COMPUTED_VALUE"""),3.0) -> 3 | T19: =IFERROR(__xludf.DUMMYFUNCTION("""COMPUTED_VALUE"""),4.0) -> 4 | U19: =IFERROR(__xludf.DUMMYFUNCTION("""COMPUTED_VALUE"""),5.0) -> 5 | V19: =IFERROR(__xludf.DUMMYFUNCTION("""COMPUTED_VALUE"""),7.0) -> 7 | W19: =IFERROR(__xludf.DUMMYFUNCTION("""COMPUTED_VALUE"""),46000.0) -> 46000 | X19: =IFERROR(__xludf.DUMMYFUNCTION("""COMPUTED_VALUE"""),46003.0) -> 46003 | Y19: =IFERROR(__xludf.DUMMYFUNCTION("""COMPUTED_VALUE"""),46008.0) -> 46008 | AF19: =IFERROR(__xludf.DUMMYFUNCTION("""COMPUTED_VALUE"""),"ヒザ巾（半寸）") -> ヒザ巾（半寸） | AH19: =IFERROR(__xludf.DUMMYFUNCTION("""COMPUTED_VALUE"""),-6.0) -> -6 | AI19: =IFERROR(__xludf.DUMMYFUNCTION("""COMPUTED_VALUE"""),-5.0) -> -5 | AJ19: =IFERROR(__xludf.DUMMYFUNCTION("""COMPUTED_VALUE"""),-4.0) -> -4 | AK19: =IFERROR(__xludf.DUMMYFUNCTION("""COMPUTED_VALUE"""),-3.0) -> -3 | AL19: =IFERROR(__xludf.DUMMYFUNCTION("""COMPUTED_VALUE"""),-2.0) -> -2 | AM19: =IFERROR(__xludf.DUMMYFUNCTION("""COMPUTED_VALUE"""),-1.0) -> -1 | AN19: =IFERROR(__xludf.DUMMYFUNCTION("""COMPUTED_VALUE"""),0.0) -> 0 | AO19: =IFERROR(__xludf.DUMMYFUNCTION("""COMPUTED_VALUE"""),1.0) -> 1 | AP19: =IFERROR(__xludf.DUMMYFUNCTION("""COMPUTED_VALUE"""),2.0) -> 2 | AQ19: =IFERROR(__xludf.DUMMYFUNCTION("""COMPUTED_VALUE"""),3.0) -> 3 | AR19: =IFERROR(__xludf.DUMMYFUNCTION("""COMPUTED_VALUE"""),4.0) -> 4 | AS19: =IFERROR(__xludf.DUMMYFUNCTION("""COMPUTED_VALUE"""),5.0) -> 5 | AT19: =IFERROR(__xludf.DUMMYFUNCTION("""COMPUTED_VALUE"""),5.0) -> 5 | AU19: =IFERROR(__xludf.DUMMYFUNCTION("""COMPUTED_VALUE"""),45996.0) -> 45996 | AV19: =IFERROR(__xludf.DUMMYFUNCTION("""COMPUTED_VALUE"""),46002.0) -> 46002 | AW19: =IFERROR(__xludf.DUMMYFUNCTION("""COMPUTED_VALUE"""),46007.0) -> 46007 | BB19: =IFERROR(__xludf.DUMMYFUNCTION("""COMPUTED_VALUE"""),"STRETCH MOLESKIN") -> STRETCH MOLESKIN | BC19: =IFERROR(__xludf.DUMMYFUNCTION("""COMPUTED_VALUE"""),"C240008~C240015") -> C240008~C240015 | BD19: =IFERROR(__xludf.DUMMYFUNCTION("""COMPUTED_VALUE"""),"出しNG（再製作）ジャケット・スラックス") -> 出しNG（再製作）ジャケット・スラックス
E20: =IFERROR(__xludf.DUMMYFUNCTION("""COMPUTED_VALUE"""),"ノーベント") -> ノーベント | F20: =IFERROR(__xludf.DUMMYFUNCTION("""COMPUTED_VALUE"""),-10.0) -> -10 | G20: =IFERROR(__xludf.DUMMYFUNCTION("""COMPUTED_VALUE"""),-9.0) -> -9 | H20: =IFERROR(__xludf.DUMMYFUNCTION("""COMPUTED_VALUE"""),-8.0) -> -8 | I20: =IFERROR(__xludf.DUMMYFUNCTION("""COMPUTED_VALUE"""),-7.0) -> -7 | J20: =IFERROR(__xludf.DUMMYFUNCTION("""COMPUTED_VALUE"""),-6.0) -> -6 | K20: =IFERROR(__xludf.DUMMYFUNCTION("""COMPUTED_VALUE"""),-5.0) -> -5 | L20: =IFERROR(__xludf.DUMMYFUNCTION("""COMPUTED_VALUE"""),-4.0) -> -4 | M20: =IFERROR(__xludf.DUMMYFUNCTION("""COMPUTED_VALUE"""),-3.0) -> -3 | N20: =IFERROR(__xludf.DUMMYFUNCTION("""COMPUTED_VALUE"""),-2.0) -> -2 | O20: =IFERROR(__xludf.DUMMYFUNCTION("""COMPUTED_VALUE"""),-1.0) -> -1 | P20: =IFERROR(__xludf.DUMMYFUNCTION("""COMPUTED_VALUE"""),0.0) -> 0 | Q20: =IFERROR(__xludf.DUMMYFUNCTION("""COMPUTED_VALUE"""),1.0) -> 1 | R20: =IFERROR(__xludf.DUMMYFUNCTION("""COMPUTED_VALUE"""),2.0) -> 2 | S20: =IFERROR(__xludf.DUMMYFUNCTION("""COMPUTED_VALUE"""),3.0) -> 3 | T20: =IFERROR(__xludf.DUMMYFUNCTION("""COMPUTED_VALUE"""),4.0) -> 4 | U20: =IFERROR(__xludf.DUMMYFUNCTION("""COMPUTED_VALUE"""),5.0) -> 5 | V20: =IFERROR(__xludf.DUMMYFUNCTION("""COMPUTED_VALUE"""),7.0) -> 7 | W20: =IFERROR(__xludf.DUMMYFUNCTION("""COMPUTED_VALUE"""),46000.0) -> 46000 | X20: =IFERROR(__xludf.DUMMYFUNCTION("""COMPUTED_VALUE"""),46003.0) -> 46003 | Y20: =IFERROR(__xludf.DUMMYFUNCTION("""COMPUTED_VALUE"""),46008.0) -> 46008 | AF20: =IFERROR(__xludf.DUMMYFUNCTION("""COMPUTED_VALUE"""),"裾口巾（半寸）") -> 裾口巾（半寸） | AH20: =IFERROR(__xludf.DUMMYFUNCTION("""COMPUTED_VALUE"""),-6.0) -> -6 | AI20: =IFERROR(__xludf.DUMMYFUNCTION("""COMPUTED_VALUE"""),-5.0) -> -5 | AJ20: =IFERROR(__xludf.DUMMYFUNCTION("""COMPUTED_VALUE"""),-4.0) -> -4 | AK20: =IFERROR(__xludf.DUMMYFUNCTION("""COMPUTED_VALUE"""),-3.0) -> -3 | AL20: =IFERROR(__xludf.DUMMYFUNCTION("""COMPUTED_VALUE"""),-2.0) -> -2 | AM20: =IFERROR(__xludf.DUMMYFUNCTION("""COMPUTED_VALUE"""),-1.0) -> -1 | AN20: =IFERROR(__xludf.DUMMYFUNCTION("""COMPUTED_VALUE"""),0.0) -> 0 | AO20: =IFERROR(__xludf.DUMMYFUNCTION("""COMPUTED_VALUE"""),1.0) -> 1 | AP20: =IFERROR(__xludf.DUMMYFUNCTION("""COMPUTED_VALUE"""),2.0) -> 2 | AQ20: =IFERROR(__xludf.DUMMYFUNCTION("""COMPUTED_VALUE"""),3.0) -> 3 | AR20: =IFERROR(__xludf.DUMMYFUNCTION("""COMPUTED_VALUE"""),4.0) -> 4 | AS20: =IFERROR(__xludf.DUMMYFUNCTION("""COMPUTED_VALUE"""),5.0) -> 5 | AT20: =IFERROR(__xludf.DUMMYFUNCTION("""COMPUTED_VALUE"""),5.0) -> 5 | AU20: =IFERROR(__xludf.DUMMYFUNCTION("""COMPUTED_VALUE"""),45996.0) -> 45996 | AV20: =IFERROR(__xludf.DUMMYFUNCTION("""COMPUTED_VALUE"""),46002.0) -> 46002 | AW20: =IFERROR(__xludf.DUMMYFUNCTION("""COMPUTED_VALUE"""),46007.0) -> 46007 | BB20: =IFERROR(__xludf.DUMMYFUNCTION("""COMPUTED_VALUE"""),"EASY CARE COTTON JAPAN FABRIC from BANSHU") -> EASY CARE COTTON JAPAN FABRIC from BANSHU | BC20: =IFERROR(__xludf.DUMMYFUNCTION("""COMPUTED_VALUE"""),"C240016~C240022") -> C240016~C240022 | BD20: =IFERROR(__xludf.DUMMYFUNCTION("""COMPUTED_VALUE"""),"出しNG（再製作）ジャケット・スラックス") -> 出しNG（再製作）ジャケット・スラックス
C21: =IFERROR(__xludf.DUMMYFUNCTION("""COMPUTED_VALUE"""),"補正") -> 補正 | D21: =IFERROR(__xludf.DUMMYFUNCTION("""COMPUTED_VALUE"""),"けまわし") -> けまわし | E21: =IFERROR(__xludf.DUMMYFUNCTION("""COMPUTED_VALUE"""),"※逆補正を含む、補正が入っていない時のみ、お直し可") -> ※逆補正を含む、補正が入っていない時のみ、お直し可 | N21: =IFERROR(__xludf.DUMMYFUNCTION("""COMPUTED_VALUE"""),-1.0) -> -1 | O21: =IFERROR(__xludf.DUMMYFUNCTION("""COMPUTED_VALUE"""),-0.5) -> -0.5 | V21: =IFERROR(__xludf.DUMMYFUNCTION("""COMPUTED_VALUE"""),10.0) -> 10 | W21: =IFERROR(__xludf.DUMMYFUNCTION("""COMPUTED_VALUE"""),46003.0) -> 46003 | X21: =IFERROR(__xludf.DUMMYFUNCTION("""COMPUTED_VALUE"""),46003.0) -> 46003 | Y21: =IFERROR(__xludf.DUMMYFUNCTION("""COMPUTED_VALUE"""),46008.0) -> 46008 | AE21: =IFERROR(__xludf.DUMMYFUNCTION("""COMPUTED_VALUE"""),"縫製") -> 縫製 | AF21: =IFERROR(__xludf.DUMMYFUNCTION("""COMPUTED_VALUE"""),"ベルトループ付け直し") -> ベルトループ付け直し | AG21: =IFERROR(__xludf.DUMMYFUNCTION("""COMPUTED_VALUE"""),"縫製/依頼シートをつけてTB出荷") -> 縫製/依頼シートをつけてTB出荷 | AT21: =IFERROR(__xludf.DUMMYFUNCTION("""COMPUTED_VALUE"""),7.0) -> 7 | AU21: =IFERROR(__xludf.DUMMYFUNCTION("""COMPUTED_VALUE"""),46000.0) -> 46000 | BB21: =IFERROR(__xludf.DUMMYFUNCTION("""COMPUTED_VALUE"""),"STRETCH CORDUROY") -> STRETCH CORDUROY | BC21: =IFERROR(__xludf.DUMMYFUNCTION("""COMPUTED_VALUE"""),"C240131~C240137") -> C240131~C240137 | BD21: =IFERROR(__xludf.DUMMYFUNCTION("""COMPUTED_VALUE"""),"出しNG（再製作）ジャケット・スラックス") -> 出しNG（再製作）ジャケット・スラックス
D22: =IFERROR(__xludf.DUMMYFUNCTION("""COMPUTED_VALUE"""),"つきとり") -> つきとり | E22: =IFERROR(__xludf.DUMMYFUNCTION("""COMPUTED_VALUE"""),"※逆補正を含む、補正が入っていない時のみ、お直し可") -> ※逆補正を含む、補正が入っていない時のみ、お直し可 | O22: =IFERROR(__xludf.DUMMYFUNCTION("""COMPUTED_VALUE"""),-1.0) -> -1 | V22: =IFERROR(__xludf.DUMMYFUNCTION("""COMPUTED_VALUE"""),10.0) -> 10 | W22: =IFERROR(__xludf.DUMMYFUNCTION("""COMPUTED_VALUE"""),46003.0) -> 46003 | X22: =IFERROR(__xludf.DUMMYFUNCTION("""COMPUTED_VALUE"""),46003.0) -> 46003 | Y22: =IFERROR(__xludf.DUMMYFUNCTION("""COMPUTED_VALUE"""),46008.0) -> 46008 | AF22: =IFERROR(__xludf.DUMMYFUNCTION("""COMPUTED_VALUE"""),"裾まつり直し") -> 裾まつり直し | AG22: =IFERROR(__xludf.DUMMYFUNCTION("""COMPUTED_VALUE"""),"縫製/依頼シートをつけてTB出荷") -> 縫製/依頼シートをつけてTB出荷 | AT22: =IFERROR(__xludf.DUMMYFUNCTION("""COMPUTED_VALUE"""),4.0) -> 4 | AU22: =IFERROR(__xludf.DUMMYFUNCTION("""COMPUTED_VALUE"""),45995.0) -> 45995 | BB22: =IFERROR(__xludf.DUMMYFUNCTION("""COMPUTED_VALUE"""),"なめらかで極細の糸から創り上げた、着心地抜群のストレッチ新素材") -> なめらかで極細の糸から創り上げた、着心地抜群のストレッチ新素材 | BC22: =IFERROR(__xludf.DUMMYFUNCTION("""COMPUTED_VALUE"""),"W240001~W240003") -> W240001~W240003 | BD22: =IFERROR(__xludf.DUMMYFUNCTION("""COMPUTED_VALUE"""),"出しNG（再製作）ジャケット・スラックス") -> 出しNG（再製作）ジャケット・スラックス
D23: =IFERROR(__xludf.DUMMYFUNCTION("""COMPUTED_VALUE"""),"鎌浅") -> 鎌浅 | E23: =IFERROR(__xludf.DUMMYFUNCTION("""COMPUTED_VALUE"""),"※逆補正を含む、補正が入っていない時のみ、お直し可") -> ※逆補正を含む、補正が入っていない時のみ、お直し可 | O23: =IFERROR(__xludf.DUMMYFUNCTION("""COMPUTED_VALUE"""),-1.0) -> -1 | V23: =IFERROR(__xludf.DUMMYFUNCTION("""COMPUTED_VALUE"""),10.0) -> 10 | W23: =IFERROR(__xludf.DUMMYFUNCTION("""COMPUTED_VALUE"""),46003.0) -> 46003 | X23: =IFERROR(__xludf.DUMMYFUNCTION("""COMPUTED_VALUE"""),46003.0) -> 46003 | Y23: =IFERROR(__xludf.DUMMYFUNCTION("""COMPUTED_VALUE"""),46008.0) -> 46008 | AF23: =IFERROR(__xludf.DUMMYFUNCTION("""COMPUTED_VALUE"""),"裏地ほつれ補修（膝裏地裾部分のみ）") -> 裏地ほつれ補修（膝裏地裾部分のみ） | AG23: =IFERROR(__xludf.DUMMYFUNCTION("""COMPUTED_VALUE"""),"縫製/依頼シートをつけてTB出荷") -> 縫製/依頼シートをつけてTB出荷 | AT23: =IFERROR(__xludf.DUMMYFUNCTION("""COMPUTED_VALUE"""),4.0) -> 4 | AU23: =IFERROR(__xludf.DUMMYFUNCTION("""COMPUTED_VALUE"""),45995.0) -> 45995 | BB23: =IFERROR(__xludf.DUMMYFUNCTION("""COMPUTED_VALUE"""),"Silky Drape Satin ") -> Silky Drape Satin | BC23: =IFERROR(__xludf.DUMMYFUNCTION("""COMPUTED_VALUE"""),"F250001~F250003 ") -> F250001~F250003 | BD23: =IFERROR(__xludf.DUMMYFUNCTION("""COMPUTED_VALUE"""),"出しNG（再製作）ジャケット・スラックス。スカート") -> 出しNG（再製作）ジャケット・スラックス。スカート
AF24: =IFERROR(__xludf.DUMMYFUNCTION("""COMPUTED_VALUE"""),"緩くなったボタンの付け直し") -> 緩くなったボタンの付け直し | AG24: =IFERROR(__xludf.DUMMYFUNCTION("""COMPUTED_VALUE"""),"縫製/依頼シートをつけてTB出荷") -> 縫製/依頼シートをつけてTB出荷 | AT24: =IFERROR(__xludf.DUMMYFUNCTION("""COMPUTED_VALUE"""),4.0) -> 4 | AU24: =IFERROR(__xludf.DUMMYFUNCTION("""COMPUTED_VALUE"""),45995.0) -> 45995 | BB24: =IFERROR(__xludf.DUMMYFUNCTION("""COMPUTED_VALUE"""),"TECH CORDUROY JERSEY ") -> TECH CORDUROY JERSEY | BC24: =IFERROR(__xludf.DUMMYFUNCTION("""COMPUTED_VALUE"""),"C250070〜C250074") -> C250070〜C250074 | BD24: =IFERROR(__xludf.DUMMYFUNCTION("""COMPUTED_VALUE"""),"出しNG（再製作）ジャケット・スラックス") -> 出しNG（再製作）ジャケット・スラックス
B25: =IFERROR(__xludf.DUMMYFUNCTION("""COMPUTED_VALUE"""),"ベスト") -> ベスト | C25: =IFERROR(__xludf.DUMMYFUNCTION("""COMPUTED_VALUE"""),"サイズ") -> サイズ | D25: =IFERROR(__xludf.DUMMYFUNCTION("""COMPUTED_VALUE"""),"バスト") -> バスト | F25: =IFERROR(__xludf.DUMMYFUNCTION("""COMPUTED_VALUE"""),-10.0) -> -10 | G25: =IFERROR(__xludf.DUMMYFUNCTION("""COMPUTED_VALUE"""),-9.0) -> -9 | H25: =IFERROR(__xludf.DUMMYFUNCTION("""COMPUTED_VALUE"""),-8.0) -> -8 | I25: =IFERROR(__xludf.DUMMYFUNCTION("""COMPUTED_VALUE"""),-7.0) -> -7 | J25: =IFERROR(__xludf.DUMMYFUNCTION("""COMPUTED_VALUE"""),-6.0) -> -6 | K25: =IFERROR(__xludf.DUMMYFUNCTION("""COMPUTED_VALUE"""),-5.0) -> -5 | L25: =IFERROR(__xludf.DUMMYFUNCTION("""COMPUTED_VALUE"""),-4.0) -> -4 | M25: =IFERROR(__xludf.DUMMYFUNCTION("""COMPUTED_VALUE"""),-3.0) -> -3 | N25: =IFERROR(__xludf.DUMMYFUNCTION("""COMPUTED_VALUE"""),-2.0) -> -2 | O25: =IFERROR(__xludf.DUMMYFUNCTION("""COMPUTED_VALUE"""),-1.0) -> -1 | P25: =IFERROR(__xludf.DUMMYFUNCTION("""COMPUTED_VALUE"""),0.0) -> 0 | Q25: =IFERROR(__xludf.DUMMYFUNCTION("""COMPUTED_VALUE"""),1.0) -> 1 | R25: =IFERROR(__xludf.DUMMYFUNCTION("""COMPUTED_VALUE"""),2.0) -> 2 | S25: =IFERROR(__xludf.DUMMYFUNCTION("""COMPUTED_VALUE"""),3.0) -> 3 | T25: =IFERROR(__xludf.DUMMYFUNCTION("""COMPUTED_VALUE"""),4.0) -> 4 | U25: =IFERROR(__xludf.DUMMYFUNCTION("""COMPUTED_VALUE"""),5.0) -> 5 | V25: =IFERROR(__xludf.DUMMYFUNCTION("""COMPUTED_VALUE"""),7.0) -> 7 | W25: =IFERROR(__xludf.DUMMYFUNCTION("""COMPUTED_VALUE"""),46000.0) -> 46000 | X25: =IFERROR(__xludf.DUMMYFUNCTION("""COMPUTED_VALUE"""),46003.0) -> 46003 | Y25: =IFERROR(__xludf.DUMMYFUNCTION("""COMPUTED_VALUE"""),46008.0) -> 46008 | AF25: =IFERROR(__xludf.DUMMYFUNCTION("""COMPUTED_VALUE"""),"パンク") -> パンク | AG25: =IFERROR(__xludf.DUMMYFUNCTION("""COMPUTED_VALUE"""),"縫製/依頼シートをつけてTB出荷") -> 縫製/依頼シートをつけてTB出荷 | AT25: =IFERROR(__xludf.DUMMYFUNCTION("""COMPUTED_VALUE"""),4.0) -> 4 | AU25: =IFERROR(__xludf.DUMMYFUNCTION("""COMPUTED_VALUE"""),45995.0) -> 45995
D26: =IFERROR(__xludf.DUMMYFUNCTION("""COMPUTED_VALUE"""),"ウエスト") -> ウエスト | F26: =IFERROR(__xludf.DUMMYFUNCTION("""COMPUTED_VALUE"""),-10.0) -> -10 | G26: =IFERROR(__xludf.DUMMYFUNCTION("""COMPUTED_VALUE"""),-9.0) -> -9 | H26: =IFERROR(__xludf.DUMMYFUNCTION("""COMPUTED_VALUE"""),-8.0) -> -8 | I26: =IFERROR(__xludf.DUMMYFUNCTION("""COMPUTED_VALUE"""),-7.0) -> -7 | J26: =IFERROR(__xludf.DUMMYFUNCTION("""COMPUTED_VALUE"""),-6.0) -> -6 | K26: =IFERROR(__xludf.DUMMYFUNCTION("""COMPUTED_VALUE"""),-5.0) -> -5 | L26: =IFERROR(__xludf.DUMMYFUNCTION("""COMPUTED_VALUE"""),-4.0) -> -4 | M26: =IFERROR(__xludf.DUMMYFUNCTION("""COMPUTED_VALUE"""),-3.0) -> -3 | N26: =IFERROR(__xludf.DUMMYFUNCTION("""COMPUTED_VALUE"""),-2.0) -> -2 | O26: =IFERROR(__xludf.DUMMYFUNCTION("""COMPUTED_VALUE"""),-1.0) -> -1 | P26: =IFERROR(__xludf.DUMMYFUNCTION("""COMPUTED_VALUE"""),0.0) -> 0 | Q26: =IFERROR(__xludf.DUMMYFUNCTION("""COMPUTED_VALUE"""),1.0) -> 1 | R26: =IFERROR(__xludf.DUMMYFUNCTION("""COMPUTED_VALUE"""),2.0) -> 2 | S26: =IFERROR(__xludf.DUMMYFUNCTION("""COMPUTED_VALUE"""),3.0) -> 3 | T26: =IFERROR(__xludf.DUMMYFUNCTION("""COMPUTED_VALUE"""),4.0) -> 4 | U26: =IFERROR(__xludf.DUMMYFUNCTION("""COMPUTED_VALUE"""),5.0) -> 5 | V26: =IFERROR(__xludf.DUMMYFUNCTION("""COMPUTED_VALUE"""),7.0) -> 7 | W26: =IFERROR(__xludf.DUMMYFUNCTION("""COMPUTED_VALUE"""),46000.0) -> 46000 | X26: =IFERROR(__xludf.DUMMYFUNCTION("""COMPUTED_VALUE"""),46003.0) -> 46003 | Y26: =IFERROR(__xludf.DUMMYFUNCTION("""COMPUTED_VALUE"""),46008.0) -> 46008 | AF26: =IFERROR(__xludf.DUMMYFUNCTION("""COMPUTED_VALUE"""),"たたきお直し") -> たたきお直し | AG26: =IFERROR(__xludf.DUMMYFUNCTION("""COMPUTED_VALUE"""),"縫製/依頼シートをつけてTB出荷") -> 縫製/依頼シートをつけてTB出荷 | AT26: =IFERROR(__xludf.DUMMYFUNCTION("""COMPUTED_VALUE"""),7.0) -> 7 | AU26: =IFERROR(__xludf.DUMMYFUNCTION("""COMPUTED_VALUE"""),46000.0) -> 46000
D27: =IFERROR(__xludf.DUMMYFUNCTION("""COMPUTED_VALUE"""),"着丈") -> 着丈 | F27: =IFERROR(__xludf.DUMMYFUNCTION("""COMPUTED_VALUE"""),-10.0) -> -10 | G27: =IFERROR(__xludf.DUMMYFUNCTION("""COMPUTED_VALUE"""),-9.0) -> -9 | H27: =IFERROR(__xludf.DUMMYFUNCTION("""COMPUTED_VALUE"""),-8.0) -> -8 | I27: =IFERROR(__xludf.DUMMYFUNCTION("""COMPUTED_VALUE"""),-7.0) -> -7 | J27: =IFERROR(__xludf.DUMMYFUNCTION("""COMPUTED_VALUE"""),-6.0) -> -6 | K27: =IFERROR(__xludf.DUMMYFUNCTION("""COMPUTED_VALUE"""),-5.0) -> -5 | L27: =IFERROR(__xludf.DUMMYFUNCTION("""COMPUTED_VALUE"""),-4.0) -> -4 | M27: =IFERROR(__xludf.DUMMYFUNCTION("""COMPUTED_VALUE"""),-3.0) -> -3 | N27: =IFERROR(__xludf.DUMMYFUNCTION("""COMPUTED_VALUE"""),-2.0) -> -2 | O27: =IFERROR(__xludf.DUMMYFUNCTION("""COMPUTED_VALUE"""),-1.0) -> -1 | P27: =IFERROR(__xludf.DUMMYFUNCTION("""COMPUTED_VALUE"""),0.0) -> 0 | Q27: =IFERROR(__xludf.DUMMYFUNCTION("""COMPUTED_VALUE"""),0.5) -> 0.5 | R27: =IFERROR(__xludf.DUMMYFUNCTION("""COMPUTED_VALUE"""),2.0) -> 2 | S27: =IFERROR(__xludf.DUMMYFUNCTION("""COMPUTED_VALUE"""),3.0) -> 3 | T27: =IFERROR(__xludf.DUMMYFUNCTION("""COMPUTED_VALUE"""),4.0) -> 4 | U27: =IFERROR(__xludf.DUMMYFUNCTION("""COMPUTED_VALUE"""),5.0) -> 5 | V27: =IFERROR(__xludf.DUMMYFUNCTION("""COMPUTED_VALUE"""),7.0) -> 7 | W27: =IFERROR(__xludf.DUMMYFUNCTION("""COMPUTED_VALUE"""),46000.0) -> 46000 | X27: =IFERROR(__xludf.DUMMYFUNCTION("""COMPUTED_VALUE"""),46003.0) -> 46003 | Y27: =IFERROR(__xludf.DUMMYFUNCTION("""COMPUTED_VALUE"""),46008.0) -> 46008
C28: =IFERROR(__xludf.DUMMYFUNCTION("""COMPUTED_VALUE"""),"縫製") -> 縫製 | D28: =IFERROR(__xludf.DUMMYFUNCTION("""COMPUTED_VALUE"""),"バスト") -> バスト | E28: =IFERROR(__xludf.DUMMYFUNCTION("""COMPUTED_VALUE"""),"ベルトループ交換") -> ベルトループ交換 | V28: =IFERROR(__xludf.DUMMYFUNCTION("""COMPUTED_VALUE"""),4.0) -> 4 | W28: =IFERROR(__xludf.DUMMYFUNCTION("""COMPUTED_VALUE"""),45995.0) -> 45995 | X28: =IFERROR(__xludf.DUMMYFUNCTION("""COMPUTED_VALUE"""),46003.0) -> 46003 | Y28: =IFERROR(__xludf.DUMMYFUNCTION("""COMPUTED_VALUE"""),46008.0) -> 46008 | AD28: =IFERROR(__xludf.DUMMYFUNCTION("""COMPUTED_VALUE"""),"チノ") -> チノ | AE28: =IFERROR(__xludf.DUMMYFUNCTION("""COMPUTED_VALUE"""),"サイズ") -> サイズ | AF28: =IFERROR(__xludf.DUMMYFUNCTION("""COMPUTED_VALUE"""),"ウエスト") -> ウエスト | AH28: =IFERROR(__xludf.DUMMYFUNCTION("""COMPUTED_VALUE"""),-6.0) -> -6 | AI28: =IFERROR(__xludf.DUMMYFUNCTION("""COMPUTED_VALUE"""),-5.0) -> -5 | AJ28: =IFERROR(__xludf.DUMMYFUNCTION("""COMPUTED_VALUE"""),-4.0) -> -4 | AK28: =IFERROR(__xludf.DUMMYFUNCTION("""COMPUTED_VALUE"""),-3.0) -> -3 | AL28: =IFERROR(__xludf.DUMMYFUNCTION("""COMPUTED_VALUE"""),-2.0) -> -2 | AM28: =IFERROR(__xludf.DUMMYFUNCTION("""COMPUTED_VALUE"""),-1.0) -> -1 | AN28: =IFERROR(__xludf.DUMMYFUNCTION("""COMPUTED_VALUE"""),0.0) -> 0 | AO28: =IFERROR(__xludf.DUMMYFUNCTION("""COMPUTED_VALUE"""),1.0) -> 1 | AP28: =IFERROR(__xludf.DUMMYFUNCTION("""COMPUTED_VALUE"""),2.0) -> 2 | AQ28: =IFERROR(__xludf.DUMMYFUNCTION("""COMPUTED_VALUE"""),3.0) -> 3 | AR28: =IFERROR(__xludf.DUMMYFUNCTION("""COMPUTED_VALUE"""),4.0) -> 4 | AS28: =IFERROR(__xludf.DUMMYFUNCTION("""COMPUTED_VALUE"""),5.0) -> 5 | AT28: =IFERROR(__xludf.DUMMYFUNCTION("""COMPUTED_VALUE"""),5.0) -> 5 | AU28: =IFERROR(__xludf.DUMMYFUNCTION("""COMPUTED_VALUE"""),45996.0) -> 45996 | AV28: =IFERROR(__xludf.DUMMYFUNCTION("""COMPUTED_VALUE"""),46002.0) -> 46002 | AW28: =IFERROR(__xludf.DUMMYFUNCTION("""COMPUTED_VALUE"""),46007.0) -> 46007
D29: =IFERROR(__xludf.DUMMYFUNCTION("""COMPUTED_VALUE"""),"ウエスト") -> ウエスト | E29: =IFERROR(__xludf.DUMMYFUNCTION("""COMPUTED_VALUE"""),"ボタン付け替え") -> ボタン付け替え | V29: =IFERROR(__xludf.DUMMYFUNCTION("""COMPUTED_VALUE"""),4.0) -> 4 | W29: =IFERROR(__xludf.DUMMYFUNCTION("""COMPUTED_VALUE"""),45995.0) -> 45995 | X29: =IFERROR(__xludf.DUMMYFUNCTION("""COMPUTED_VALUE"""),46003.0) -> 46003 | Y29: =IFERROR(__xludf.DUMMYFUNCTION("""COMPUTED_VALUE"""),46008.0) -> 46008 | AF29: =IFERROR(__xludf.DUMMYFUNCTION("""COMPUTED_VALUE"""),"股上") -> 股上 | AH29: =IFERROR(__xludf.DUMMYFUNCTION("""COMPUTED_VALUE"""),-6.0) -> -6 | AI29: =IFERROR(__xludf.DUMMYFUNCTION("""COMPUTED_VALUE"""),-5.0) -> -5 | AJ29: =IFERROR(__xludf.DUMMYFUNCTION("""COMPUTED_VALUE"""),-3.0) -> -3 | AK29: =IFERROR(__xludf.DUMMYFUNCTION("""COMPUTED_VALUE"""),-2.0) -> -2 | AL29: =IFERROR(__xludf.DUMMYFUNCTION("""COMPUTED_VALUE"""),-1.0) -> -1 | AM29: =IFERROR(__xludf.DUMMYFUNCTION("""COMPUTED_VALUE"""),-0.5) -> -0.5 | AN29: =IFERROR(__xludf.DUMMYFUNCTION("""COMPUTED_VALUE"""),0.0) -> 0 | AO29: =IFERROR(__xludf.DUMMYFUNCTION("""COMPUTED_VALUE"""),1.0) -> 1 | AP29: =IFERROR(__xludf.DUMMYFUNCTION("""COMPUTED_VALUE"""),2.0) -> 2 | AQ29: =IFERROR(__xludf.DUMMYFUNCTION("""COMPUTED_VALUE"""),3.0) -> 3 | AR29: =IFERROR(__xludf.DUMMYFUNCTION("""COMPUTED_VALUE"""),4.0) -> 4 | AS29: =IFERROR(__xludf.DUMMYFUNCTION("""COMPUTED_VALUE"""),5.0) -> 5 | AT29: =IFERROR(__xludf.DUMMYFUNCTION("""COMPUTED_VALUE"""),7.0) -> 7 | AU29: =IFERROR(__xludf.DUMMYFUNCTION("""COMPUTED_VALUE"""),46000.0) -> 46000 | AV29: =IFERROR(__xludf.DUMMYFUNCTION("""COMPUTED_VALUE"""),46002.0) -> 46002 | AW29: =IFERROR(__xludf.DUMMYFUNCTION("""COMPUTED_VALUE"""),46007.0) -> 46007
D30: =IFERROR(__xludf.DUMMYFUNCTION("""COMPUTED_VALUE"""),"着丈") -> 着丈 | E30: =IFERROR(__xludf.DUMMYFUNCTION("""COMPUTED_VALUE"""),"裏地ほつれ補修（裾）") -> 裏地ほつれ補修（裾） | V30: =IFERROR(__xludf.DUMMYFUNCTION("""COMPUTED_VALUE"""),4.0) -> 4 | W30: =IFERROR(__xludf.DUMMYFUNCTION("""COMPUTED_VALUE"""),45995.0) -> 45995 | X30: =IFERROR(__xludf.DUMMYFUNCTION("""COMPUTED_VALUE"""),46003.0) -> 46003 | Y30: =IFERROR(__xludf.DUMMYFUNCTION("""COMPUTED_VALUE"""),46008.0) -> 46008 | AF30: =IFERROR(__xludf.DUMMYFUNCTION("""COMPUTED_VALUE"""),"股下") -> 股下 | AG30: =IFERROR(__xludf.DUMMYFUNCTION("""COMPUTED_VALUE"""),"シングル") -> シングル | AH30: =IFERROR(__xludf.DUMMYFUNCTION("""COMPUTED_VALUE"""),-6.0) -> -6 | AI30: =IFERROR(__xludf.DUMMYFUNCTION("""COMPUTED_VALUE"""),-5.0) -> -5 | AJ30: =IFERROR(__xludf.DUMMYFUNCTION("""COMPUTED_VALUE"""),-4.0) -> -4 | AK30: =IFERROR(__xludf.DUMMYFUNCTION("""COMPUTED_VALUE"""),-3.0) -> -3 | AL30: =IFERROR(__xludf.DUMMYFUNCTION("""COMPUTED_VALUE"""),-2.0) -> -2 | AM30: =IFERROR(__xludf.DUMMYFUNCTION("""COMPUTED_VALUE"""),-1.0) -> -1 | AN30: =IFERROR(__xludf.DUMMYFUNCTION("""COMPUTED_VALUE"""),0.0) -> 0 | AO30: =IFERROR(__xludf.DUMMYFUNCTION("""COMPUTED_VALUE"""),1.0) -> 1 | AP30: =IFERROR(__xludf.DUMMYFUNCTION("""COMPUTED_VALUE"""),2.0) -> 2 | AQ30: =IFERROR(__xludf.DUMMYFUNCTION("""COMPUTED_VALUE"""),3.0) -> 3 | AR30: =IFERROR(__xludf.DUMMYFUNCTION("""COMPUTED_VALUE"""),4.0) -> 4 | AS30: =IFERROR(__xludf.DUMMYFUNCTION("""COMPUTED_VALUE"""),5.0) -> 5 | AT30: =IFERROR(__xludf.DUMMYFUNCTION("""COMPUTED_VALUE"""),5.0) -> 5 | AU30: =IFERROR(__xludf.DUMMYFUNCTION("""COMPUTED_VALUE"""),45996.0) -> 45996 | AV30: =IFERROR(__xludf.DUMMYFUNCTION("""COMPUTED_VALUE"""),46002.0) -> 46002 | AW30: =IFERROR(__xludf.DUMMYFUNCTION("""COMPUTED_VALUE"""),46007.0) -> 46007
AG31: =IFERROR(__xludf.DUMMYFUNCTION("""COMPUTED_VALUE"""),"ダブル") -> ダブル | AH31: =IFERROR(__xludf.DUMMYFUNCTION("""COMPUTED_VALUE"""),-6.0) -> -6 | AI31: =IFERROR(__xludf.DUMMYFUNCTION("""COMPUTED_VALUE"""),-5.0) -> -5 | AJ31: =IFERROR(__xludf.DUMMYFUNCTION("""COMPUTED_VALUE"""),-4.0) -> -4 | AK31: =IFERROR(__xludf.DUMMYFUNCTION("""COMPUTED_VALUE"""),-3.0) -> -3 | AL31: =IFERROR(__xludf.DUMMYFUNCTION("""COMPUTED_VALUE"""),-2.0) -> -2 | AM31: =IFERROR(__xludf.DUMMYFUNCTION("""COMPUTED_VALUE"""),-1.0) -> -1 | AN31: =IFERROR(__xludf.DUMMYFUNCTION("""COMPUTED_VALUE"""),0.0) -> 0 | AO31: =IFERROR(__xludf.DUMMYFUNCTION("""COMPUTED_VALUE"""),1.0) -> 1 | AP31: =IFERROR(__xludf.DUMMYFUNCTION("""COMPUTED_VALUE"""),2.0) -> 2 | AQ31: =IFERROR(__xludf.DUMMYFUNCTION("""COMPUTED_VALUE"""),3.0) -> 3 | AR31: =IFERROR(__xludf.DUMMYFUNCTION("""COMPUTED_VALUE"""),4.0) -> 4 | AS31: =IFERROR(__xludf.DUMMYFUNCTION("""COMPUTED_VALUE"""),5.0) -> 5 | AT31: =IFERROR(__xludf.DUMMYFUNCTION("""COMPUTED_VALUE"""),"-") -> - | AU31: =IFERROR(__xludf.DUMMYFUNCTION("""COMPUTED_VALUE"""),"-") -> - | AV31: =IFERROR(__xludf.DUMMYFUNCTION("""COMPUTED_VALUE"""),46002.0) -> 46002 | AW31: =IFERROR(__xludf.DUMMYFUNCTION("""COMPUTED_VALUE"""),46007.0) -> 46007
AG32: =IFERROR(__xludf.DUMMYFUNCTION("""COMPUTED_VALUE"""),"ステッチ") -> ステッチ | AH32: =IFERROR(__xludf.DUMMYFUNCTION("""COMPUTED_VALUE"""),-6.0) -> -6 | AI32: =IFERROR(__xludf.DUMMYFUNCTION("""COMPUTED_VALUE"""),-5.0) -> -5 | AJ32: =IFERROR(__xludf.DUMMYFUNCTION("""COMPUTED_VALUE"""),-4.0) -> -4 | AK32: =IFERROR(__xludf.DUMMYFUNCTION("""COMPUTED_VALUE"""),-3.0) -> -3 | AL32: =IFERROR(__xludf.DUMMYFUNCTION("""COMPUTED_VALUE"""),-2.0) -> -2 | AM32: =IFERROR(__xludf.DUMMYFUNCTION("""COMPUTED_VALUE"""),-1.0) -> -1 | AN32: =IFERROR(__xludf.DUMMYFUNCTION("""COMPUTED_VALUE"""),0.0) -> 0 | AO32: =IFERROR(__xludf.DUMMYFUNCTION("""COMPUTED_VALUE"""),1.0) -> 1 | AP32: =IFERROR(__xludf.DUMMYFUNCTION("""COMPUTED_VALUE"""),2.0) -> 2 | AQ32: =IFERROR(__xludf.DUMMYFUNCTION("""COMPUTED_VALUE"""),3.0) -> 3 | AR32: =IFERROR(__xludf.DUMMYFUNCTION("""COMPUTED_VALUE"""),4.0) -> 4 | AS32: =IFERROR(__xludf.DUMMYFUNCTION("""COMPUTED_VALUE"""),5.0) -> 5 | AT32: =IFERROR(__xludf.DUMMYFUNCTION("""COMPUTED_VALUE"""),"-") -> - | AU32: =IFERROR(__xludf.DUMMYFUNCTION("""COMPUTED_VALUE"""),"-") -> - | AV32: =IFERROR(__xludf.DUMMYFUNCTION("""COMPUTED_VALUE"""),46002.0) -> 46002 | AW32: =IFERROR(__xludf.DUMMYFUNCTION("""COMPUTED_VALUE"""),46007.0) -> 46007
B33: =IFERROR(__xludf.DUMMYFUNCTION("""COMPUTED_VALUE""")," シャツ長袖 タックアウト長袖") -> シャツ長袖 タックアウト長袖 | C33: =IFERROR(__xludf.DUMMYFUNCTION("""COMPUTED_VALUE"""),"サイズ") -> サイズ | D33: =IFERROR(__xludf.DUMMYFUNCTION("""COMPUTED_VALUE"""),"裄丈") -> 裄丈 | F33: =IFERROR(__xludf.DUMMYFUNCTION("""COMPUTED_VALUE"""),-10.0) -> -10 | G33: =IFERROR(__xludf.DUMMYFUNCTION("""COMPUTED_VALUE"""),-9.0) -> -9 | H33: =IFERROR(__xludf.DUMMYFUNCTION("""COMPUTED_VALUE"""),-8.0) -> -8 | I33: =IFERROR(__xludf.DUMMYFUNCTION("""COMPUTED_VALUE"""),-7.0) -> -7 | J33: =IFERROR(__xludf.DUMMYFUNCTION("""COMPUTED_VALUE"""),-6.0) -> -6 | K33: =IFERROR(__xludf.DUMMYFUNCTION("""COMPUTED_VALUE"""),-5.0) -> -5 | L33: =IFERROR(__xludf.DUMMYFUNCTION("""COMPUTED_VALUE"""),-4.0) -> -4 | M33: =IFERROR(__xludf.DUMMYFUNCTION("""COMPUTED_VALUE"""),-3.0) -> -3 | N33: =IFERROR(__xludf.DUMMYFUNCTION("""COMPUTED_VALUE"""),-2.0) -> -2 | O33: =IFERROR(__xludf.DUMMYFUNCTION("""COMPUTED_VALUE"""),-1.0) -> -1 | P33: =IFERROR(__xludf.DUMMYFUNCTION("""COMPUTED_VALUE"""),0.0) -> 0 | Q33: =IFERROR(__xludf.DUMMYFUNCTION("""COMPUTED_VALUE"""),1.0) -> 1 | R33: =IFERROR(__xludf.DUMMYFUNCTION("""COMPUTED_VALUE"""),2.0) -> 2 | S33: =IFERROR(__xludf.DUMMYFUNCTION("""COMPUTED_VALUE"""),3.0) -> 3 | T33: =IFERROR(__xludf.DUMMYFUNCTION("""COMPUTED_VALUE"""),4.0) -> 4 | U33: =IFERROR(__xludf.DUMMYFUNCTION("""COMPUTED_VALUE"""),5.0) -> 5 | V33: =IFERROR(__xludf.DUMMYFUNCTION("""COMPUTED_VALUE"""),7.0) -> 7 | W33: =IFERROR(__xludf.DUMMYFUNCTION("""COMPUTED_VALUE"""),46000.0) -> 46000 | X33: =IFERROR(__xludf.DUMMYFUNCTION("""COMPUTED_VALUE"""),46003.0) -> 46003 | Y33: =IFERROR(__xludf.DUMMYFUNCTION("""COMPUTED_VALUE"""),46008.0) -> 46008 | AF33: =IFERROR(__xludf.DUMMYFUNCTION("""COMPUTED_VALUE"""),"ワタリ巾（半寸）") -> ワタリ巾（半寸） | AH33: =IFERROR(__xludf.DUMMYFUNCTION("""COMPUTED_VALUE"""),-6.0) -> -6 | AI33: =IFERROR(__xludf.DUMMYFUNCTION("""COMPUTED_VALUE"""),-5.0) -> -5 | AJ33: =IFERROR(__xludf.DUMMYFUNCTION("""COMPUTED_VALUE"""),-4.0) -> -4 | AK33: =IFERROR(__xludf.DUMMYFUNCTION("""COMPUTED_VALUE"""),-3.0) -> -3 | AL33: =IFERROR(__xludf.DUMMYFUNCTION("""COMPUTED_VALUE"""),-2.0) -> -2 | AM33: =IFERROR(__xludf.DUMMYFUNCTION("""COMPUTED_VALUE"""),-1.0) -> -1 | AN33: =IFERROR(__xludf.DUMMYFUNCTION("""COMPUTED_VALUE"""),0.0) -> 0 | AO33: =IFERROR(__xludf.DUMMYFUNCTION("""COMPUTED_VALUE"""),1.0) -> 1 | AP33: =IFERROR(__xludf.DUMMYFUNCTION("""COMPUTED_VALUE"""),2.0) -> 2 | AQ33: =IFERROR(__xludf.DUMMYFUNCTION("""COMPUTED_VALUE"""),3.0) -> 3 | AR33: =IFERROR(__xludf.DUMMYFUNCTION("""COMPUTED_VALUE"""),4.0) -> 4 | AS33: =IFERROR(__xludf.DUMMYFUNCTION("""COMPUTED_VALUE"""),5.0) -> 5 | AT33: =IFERROR(__xludf.DUMMYFUNCTION("""COMPUTED_VALUE"""),5.0) -> 5 | AU33: =IFERROR(__xludf.DUMMYFUNCTION("""COMPUTED_VALUE"""),45996.0) -> 45996 | AV33: =IFERROR(__xludf.DUMMYFUNCTION("""COMPUTED_VALUE"""),46002.0) -> 46002 | AW33: =IFERROR(__xludf.DUMMYFUNCTION("""COMPUTED_VALUE"""),46007.0) -> 46007 | BB33: =IFERROR(__xludf.DUMMYFUNCTION("""COMPUTED_VALUE"""),"White Friday 一覧") -> White Friday 一覧
D34: =IFERROR(__xludf.DUMMYFUNCTION("""COMPUTED_VALUE"""),"襟") -> 襟 | F34: =IFERROR(__xludf.DUMMYFUNCTION("""COMPUTED_VALUE"""),-10.0) -> -10 | G34: =IFERROR(__xludf.DUMMYFUNCTION("""COMPUTED_VALUE"""),-9.0) -> -9 | H34: =IFERROR(__xludf.DUMMYFUNCTION("""COMPUTED_VALUE"""),-8.0) -> -8 | I34: =IFERROR(__xludf.DUMMYFUNCTION("""COMPUTED_VALUE"""),-7.0) -> -7 | J34: =IFERROR(__xludf.DUMMYFUNCTION("""COMPUTED_VALUE"""),-6.0) -> -6 | K34: =IFERROR(__xludf.DUMMYFUNCTION("""COMPUTED_VALUE"""),-5.0) -> -5 | L34: =IFERROR(__xludf.DUMMYFUNCTION("""COMPUTED_VALUE"""),-4.0) -> -4 | M34: =IFERROR(__xludf.DUMMYFUNCTION("""COMPUTED_VALUE"""),-3.0) -> -3 | N34: =IFERROR(__xludf.DUMMYFUNCTION("""COMPUTED_VALUE"""),-2.0) -> -2 | O34: =IFERROR(__xludf.DUMMYFUNCTION("""COMPUTED_VALUE"""),-1.0) -> -1 | P34: =IFERROR(__xludf.DUMMYFUNCTION("""COMPUTED_VALUE"""),0.0) -> 0 | Q34: =IFERROR(__xludf.DUMMYFUNCTION("""COMPUTED_VALUE"""),1.0) -> 1 | R34: =IFERROR(__xludf.DUMMYFUNCTION("""COMPUTED_VALUE"""),2.0) -> 2 | S34: =IFERROR(__xludf.DUMMYFUNCTION("""COMPUTED_VALUE"""),3.0) -> 3 | T34: =IFERROR(__xludf.DUMMYFUNCTION("""COMPUTED_VALUE"""),4.0) -> 4 | U34: =IFERROR(__xludf.DUMMYFUNCTION("""COMPUTED_VALUE"""),5.0) -> 5 | V34: =IFERROR(__xludf.DUMMYFUNCTION("""COMPUTED_VALUE"""),"-") -> - | W34: =IFERROR(__xludf.DUMMYFUNCTION("""COMPUTED_VALUE"""),"-") -> - | X34: =IFERROR(__xludf.DUMMYFUNCTION("""COMPUTED_VALUE"""),"-") -> - | Y34: =IFERROR(__xludf.DUMMYFUNCTION("""COMPUTED_VALUE"""),"-") -> - | AF34: =IFERROR(__xludf.DUMMYFUNCTION("""COMPUTED_VALUE"""),"ヒザ巾（半寸）") -> ヒザ巾（半寸） | AH34: =IFERROR(__xludf.DUMMYFUNCTION("""COMPUTED_VALUE"""),-6.0) -> -6 | AI34: =IFERROR(__xludf.DUMMYFUNCTION("""COMPUTED_VALUE"""),-5.0) -> -5 | AJ34: =IFERROR(__xludf.DUMMYFUNCTION("""COMPUTED_VALUE"""),-4.0) -> -4 | AK34: =IFERROR(__xludf.DUMMYFUNCTION("""COMPUTED_VALUE"""),-3.0) -> -3 | AL34: =IFERROR(__xludf.DUMMYFUNCTION("""COMPUTED_VALUE"""),-2.0) -> -2 | AM34: =IFERROR(__xludf.DUMMYFUNCTION("""COMPUTED_VALUE"""),-1.0) -> -1 | AN34: =IFERROR(__xludf.DUMMYFUNCTION("""COMPUTED_VALUE"""),0.0) -> 0 | AO34: =IFERROR(__xludf.DUMMYFUNCTION("""COMPUTED_VALUE"""),1.0) -> 1 | AP34: =IFERROR(__xludf.DUMMYFUNCTION("""COMPUTED_VALUE"""),2.0) -> 2 | AQ34: =IFERROR(__xludf.DUMMYFUNCTION("""COMPUTED_VALUE"""),3.0) -> 3 | AR34: =IFERROR(__xludf.DUMMYFUNCTION("""COMPUTED_VALUE"""),4.0) -> 4 | AS34: =IFERROR(__xludf.DUMMYFUNCTION("""COMPUTED_VALUE"""),5.0) -> 5 | AT34: =IFERROR(__xludf.DUMMYFUNCTION("""COMPUTED_VALUE"""),5.0) -> 5 | AU34: =IFERROR(__xludf.DUMMYFUNCTION("""COMPUTED_VALUE"""),45996.0) -> 45996 | AV34: =IFERROR(__xludf.DUMMYFUNCTION("""COMPUTED_VALUE"""),46002.0) -> 46002 | AW34: =IFERROR(__xludf.DUMMYFUNCTION("""COMPUTED_VALUE"""),46007.0) -> 46007 | BB34: =IFERROR(__xludf.DUMMYFUNCTION("""COMPUTED_VALUE"""),"なめらかで極細の糸から創り上げた、着心地抜群のストレッチ新素材") -> なめらかで極細の糸から創り上げた、着心地抜群のストレッチ新素材 | BC34: =IFERROR(__xludf.DUMMYFUNCTION("""COMPUTED_VALUE"""),"W240001") -> W240001 | BD34: =IFERROR(__xludf.DUMMYFUNCTION("""COMPUTED_VALUE"""),"出しNG（再製作）ジャケット・スラックス") -> 出しNG（再製作）ジャケット・スラックス
D35: =IFERROR(__xludf.DUMMYFUNCTION("""COMPUTED_VALUE"""),"カフス") -> カフス | F35: =IFERROR(__xludf.DUMMYFUNCTION("""COMPUTED_VALUE"""),-10.0) -> -10 | G35: =IFERROR(__xludf.DUMMYFUNCTION("""COMPUTED_VALUE"""),-9.0) -> -9 | H35: =IFERROR(__xludf.DUMMYFUNCTION("""COMPUTED_VALUE"""),-8.0) -> -8 | I35: =IFERROR(__xludf.DUMMYFUNCTION("""COMPUTED_VALUE"""),-7.0) -> -7 | J35: =IFERROR(__xludf.DUMMYFUNCTION("""COMPUTED_VALUE"""),-6.0) -> -6 | K35: =IFERROR(__xludf.DUMMYFUNCTION("""COMPUTED_VALUE"""),-5.0) -> -5 | L35: =IFERROR(__xludf.DUMMYFUNCTION("""COMPUTED_VALUE"""),-4.0) -> -4 | M35: =IFERROR(__xludf.DUMMYFUNCTION("""COMPUTED_VALUE"""),-3.0) -> -3 | N35: =IFERROR(__xludf.DUMMYFUNCTION("""COMPUTED_VALUE"""),-2.0) -> -2 | O35: =IFERROR(__xludf.DUMMYFUNCTION("""COMPUTED_VALUE"""),-1.0) -> -1 | P35: =IFERROR(__xludf.DUMMYFUNCTION("""COMPUTED_VALUE"""),0.0) -> 0 | Q35: =IFERROR(__xludf.DUMMYFUNCTION("""COMPUTED_VALUE"""),1.0) -> 1 | R35: =IFERROR(__xludf.DUMMYFUNCTION("""COMPUTED_VALUE"""),2.0) -> 2 | S35: =IFERROR(__xludf.DUMMYFUNCTION("""COMPUTED_VALUE"""),3.0) -> 3 | T35: =IFERROR(__xludf.DUMMYFUNCTION("""COMPUTED_VALUE"""),4.0) -> 4 | U35: =IFERROR(__xludf.DUMMYFUNCTION("""COMPUTED_VALUE"""),5.0) -> 5 | V35: =IFERROR(__xludf.DUMMYFUNCTION("""COMPUTED_VALUE"""),"-") -> - | W35: =IFERROR(__xludf.DUMMYFUNCTION("""COMPUTED_VALUE"""),"-") -> - | X35: =IFERROR(__xludf.DUMMYFUNCTION("""COMPUTED_VALUE"""),"-") -> - | Y35: =IFERROR(__xludf.DUMMYFUNCTION("""COMPUTED_VALUE"""),"-") -> - | AF35: =IFERROR(__xludf.DUMMYFUNCTION("""COMPUTED_VALUE"""),"裾口巾（半寸）") -> 裾口巾（半寸） | AH35: =IFERROR(__xludf.DUMMYFUNCTION("""COMPUTED_VALUE"""),-6.0) -> -6 | AI35: =IFERROR(__xludf.DUMMYFUNCTION("""COMPUTED_VALUE"""),-5.0) -> -5 | AJ35: =IFERROR(__xludf.DUMMYFUNCTION("""COMPUTED_VALUE"""),-4.0) -> -4 | AK35: =IFERROR(__xludf.DUMMYFUNCTION("""COMPUTED_VALUE"""),-3.0) -> -3 | AL35: =IFERROR(__xludf.DUMMYFUNCTION("""COMPUTED_VALUE"""),-2.0) -> -2 | AM35: =IFERROR(__xludf.DUMMYFUNCTION("""COMPUTED_VALUE"""),-1.0) -> -1 | AN35: =IFERROR(__xludf.DUMMYFUNCTION("""COMPUTED_VALUE"""),0.0) -> 0 | AO35: =IFERROR(__xludf.DUMMYFUNCTION("""COMPUTED_VALUE"""),1.0) -> 1 | AP35: =IFERROR(__xludf.DUMMYFUNCTION("""COMPUTED_VALUE"""),2.0) -> 2 | AQ35: =IFERROR(__xludf.DUMMYFUNCTION("""COMPUTED_VALUE"""),3.0) -> 3 | AR35: =IFERROR(__xludf.DUMMYFUNCTION("""COMPUTED_VALUE"""),4.0) -> 4 | AS35: =IFERROR(__xludf.DUMMYFUNCTION("""COMPUTED_VALUE"""),5.0) -> 5 | AT35: =IFERROR(__xludf.DUMMYFUNCTION("""COMPUTED_VALUE"""),5.0) -> 5 | AU35: =IFERROR(__xludf.DUMMYFUNCTION("""COMPUTED_VALUE"""),45996.0) -> 45996 | AV35: =IFERROR(__xludf.DUMMYFUNCTION("""COMPUTED_VALUE"""),46002.0) -> 46002 | AW35: =IFERROR(__xludf.DUMMYFUNCTION("""COMPUTED_VALUE"""),46007.0) -> 46007 | BB35: =IFERROR(__xludf.DUMMYFUNCTION("""COMPUTED_VALUE"""),"なめらかで極細の糸から創り上げた、着心地抜群のストレッチ新素材") -> なめらかで極細の糸から創り上げた、着心地抜群のストレッチ新素材 | BC35: =IFERROR(__xludf.DUMMYFUNCTION("""COMPUTED_VALUE"""),"W240002") -> W240002 | BD35: =IFERROR(__xludf.DUMMYFUNCTION("""COMPUTED_VALUE"""),"出しNG（再製作）ジャケット・スラックス") -> 出しNG（再製作）ジャケット・スラックス
D36: =IFERROR(__xludf.DUMMYFUNCTION("""COMPUTED_VALUE"""),"バスト") -> バスト | F36: =IFERROR(__xludf.DUMMYFUNCTION("""COMPUTED_VALUE"""),-10.0) -> -10 | G36: =IFERROR(__xludf.DUMMYFUNCTION("""COMPUTED_VALUE"""),-9.0) -> -9 | H36: =IFERROR(__xludf.DUMMYFUNCTION("""COMPUTED_VALUE"""),-8.0) -> -8 | I36: =IFERROR(__xludf.DUMMYFUNCTION("""COMPUTED_VALUE"""),-7.0) -> -7 | J36: =IFERROR(__xludf.DUMMYFUNCTION("""COMPUTED_VALUE"""),-6.0) -> -6 | K36: =IFERROR(__xludf.DUMMYFUNCTION("""COMPUTED_VALUE"""),-5.0) -> -5 | L36: =IFERROR(__xludf.DUMMYFUNCTION("""COMPUTED_VALUE"""),-4.0) -> -4 | M36: =IFERROR(__xludf.DUMMYFUNCTION("""COMPUTED_VALUE"""),-3.0) -> -3 | N36: =IFERROR(__xludf.DUMMYFUNCTION("""COMPUTED_VALUE"""),-2.0) -> -2 | O36: =IFERROR(__xludf.DUMMYFUNCTION("""COMPUTED_VALUE"""),-1.0) -> -1 | P36: =IFERROR(__xludf.DUMMYFUNCTION("""COMPUTED_VALUE"""),0.0) -> 0 | Q36: =IFERROR(__xludf.DUMMYFUNCTION("""COMPUTED_VALUE"""),1.0) -> 1 | R36: =IFERROR(__xludf.DUMMYFUNCTION("""COMPUTED_VALUE"""),2.0) -> 2 | S36: =IFERROR(__xludf.DUMMYFUNCTION("""COMPUTED_VALUE"""),3.0) -> 3 | T36: =IFERROR(__xludf.DUMMYFUNCTION("""COMPUTED_VALUE"""),4.0) -> 4 | U36: =IFERROR(__xludf.DUMMYFUNCTION("""COMPUTED_VALUE"""),5.0) -> 5 | V36: =IFERROR(__xludf.DUMMYFUNCTION("""COMPUTED_VALUE"""),7.0) -> 7 | W36: =IFERROR(__xludf.DUMMYFUNCTION("""COMPUTED_VALUE"""),46000.0) -> 46000 | X36: =IFERROR(__xludf.DUMMYFUNCTION("""COMPUTED_VALUE"""),46003.0) -> 46003 | Y36: =IFERROR(__xludf.DUMMYFUNCTION("""COMPUTED_VALUE"""),46008.0) -> 46008 | AE36: =IFERROR(__xludf.DUMMYFUNCTION("""COMPUTED_VALUE"""),"縫製") -> 縫製 | AF36: =IFERROR(__xludf.DUMMYFUNCTION("""COMPUTED_VALUE"""),"ベルトループ付け直し") -> ベルトループ付け直し | AG36: =IFERROR(__xludf.DUMMYFUNCTION("""COMPUTED_VALUE"""),"縫製/依頼シートをつけてTB出荷") -> 縫製/依頼シートをつけてTB出荷 | AT36: =IFERROR(__xludf.DUMMYFUNCTION("""COMPUTED_VALUE"""),4.0) -> 4 | AU36: =IFERROR(__xludf.DUMMYFUNCTION("""COMPUTED_VALUE"""),45995.0) -> 45995 | BB36: =IFERROR(__xludf.DUMMYFUNCTION("""COMPUTED_VALUE"""),"なめらかで極細の糸から創り上げた、着心地抜群のストレッチ新素材") -> なめらかで極細の糸から創り上げた、着心地抜群のストレッチ新素材 | BC36: =IFERROR(__xludf.DUMMYFUNCTION("""COMPUTED_VALUE"""),"W240003") -> W240003 | BD36: =IFERROR(__xludf.DUMMYFUNCTION("""COMPUTED_VALUE"""),"出しNG（再製作）ジャケット・スラックス") -> 出しNG（再製作）ジャケット・スラックス
